Workbook

Sheet Lịch kiểm kê 2025
E1: LỊCH KIỂM KÊ TỔNG 2025 | I1: GSM Báo đổi
E2: Thời gian: 01/04/2025 - 29/12/2025 | I2: Thay đổi 7-10 ngày hiện tại => mới điều chỉnh kịp
B3: SDT IT hỗ trợ khi ST gặp sự cố trong lúc kiểm kê | E3: Ngô Quang Cẩm Tú | F3: 0386446113 | M3: DONE
E4: Hoàng Ngọc Long | F4: 0981683801
E5: Tô Thanh Vinh | F5: 0877410295
E6: Nguyễn Thanh Tùng | F6: 0367910431
E7: Nguyễn Xuân Hoánh | F7: 0886485610
J8: Đã delete KK Daily | K8: Khang SOC | M8: GSM | N8: Dành cho các ST đã thực hiện kiểm kê bàn giao full 5 ngành hàng => điền ngày đã kiểm kê tương ứng vào bên dưới
A9: STT | B9: GSM | C9: ID Mart | D9: KV | E9: Tên Siêu thị | F9: Ngày kiểm kê tổng | G9: Ngày kiểm Fresh food | H9: Ngày đổ phiếu tổng | I9: Ngưng kiểm kê Daily | J9: ADMIN NOTE | K9: Đã cài lịch kiểm kê | L9: Ngày đổ phiếu tổng thực tế | M9: Note thời gian Cần tắt ONL | N9: 1.BAKERY AND DELICA | O9: 1.CHILLED AND FROZEN | P9: 1.DAIRY AND ICE CREAM | Q9: 1.FMCG | R9: 1.FRESH FOOD | S9: Ngày kiểm Fresh food thực tê | T9: Bắt đầu Ngưng Kiểm kê Daily | U9: Kết Thúc Ngưng Kiểm kê Daily
A10: =ROW()-9 -> 1 | B10: {=XLOOKUP(E10,'GSM T4.2026'!D:D,'GSM T4.2026'!F:F)} -> #N/A | C10: {=XLOOKUP(E10,Sheet6!H:H,Sheet6!G:G)} -> CTH | D10: {=XLOOKUP(E10,'GSM T4.2026'!D:D,#REF!)} -> #N/A | E10: KFM_HCM_TDU - TMDV Citihome Cát Lái - MART | F10: 12-09-25 | G10: =F10-3 -> -319334 | H10: =F10-5 -> -319336 | I10: 08/09 - 15/09 | J10: X | K10: DONE
A11: =ROW()-9 -> 2 | B11: {=XLOOKUP(E11,'GSM T4.2026'!D:D,'GSM T4.2026'!F:F)} -> #N/A | C11: {=XLOOKUP(E11,Sheet6!H:H,Sheet6!G:G)} -> LVL | D11: {=XLOOKUP(E11,'GSM T4.2026'!D:D,#REF!)} -> #N/A | E11: KFM_HCM_NBE - 166E Lê Văn Lương - MART | F11: 45906 | G11: 45904 | H11: =F11-5 -> 45901 | I11: 01/09 - 09/09 | J11: X | K11: DONE | T11: 45905 | U11: 22/05/2025
A12: =ROW()-9 -> 3 | B12: {=XLOOKUP(E12,'GSM T4.2026'!D:D,'GSM T4.2026'!F:F)} -> #N/A | C12: {=XLOOKUP(E12,Sheet6!H:H,Sheet6!G:G)} -> PTN | D12: {=XLOOKUP(E12,'GSM T4.2026'!D:D,#REF!)} -> #N/A | E12: KFM_HCM_Q07 - E72 Phú Thuận - MINI | F12: 45908 | G12: =F12-3 -> 45905 | H12: =F12-5 -> 45903 | I12: 01/09 - 11/09 | J12: X | K12: DONE | T12: 45906 | U12: 21/06/2025
A13: =ROW()-9 -> 4 | B13: {=XLOOKUP(E13,'GSM T4.2026'!D:D,'GSM T4.2026'!F:F)} -> #N/A | C13: {=XLOOKUP(E13,Sheet6!H:H,Sheet6!G:G)} -> JKD | D13: {=XLOOKUP(E13,'GSM T4.2026'!D:D,#REF!)} -> #N/A | E13: KFM_HCM_TDU - A1.04 Jamila Khang Điền - MINI | F13: 45914 | G13: =F13-3 -> 45911 | H13: =F13-5 -> 45909 | I13: 08/09 - 17/09 | J13: X | K13: DONE | T13: 45906 | U13: 21/06/2025
A14: =ROW()-9 -> 5 | B14: {=XLOOKUP(E14,'GSM T4.2026'!D:D,'GSM T4.2026'!F:F)} -> #N/A | C14: {=XLOOKUP(E14,Sheet6!H:H,Sheet6!G:G)} -> HPD | D14: {=XLOOKUP(E14,'GSM T4.2026'!D:D,#REF!)} -> #N/A | E14: KFM_BDU_DAN - 01-06 TMDV Him Lam Phú Đông - MINI | F14: 45918 | G14: =F14-3 -> 45915 | H14: =F14-5 -> 45913 | I14: 13/09 - 21/09 | J14: X | K14: DONE | T14: 45905 | U14: 15/05/2025
A15: =ROW()-9 -> 6 | B15: {=XLOOKUP(E15,'GSM T4.2026'!D:D,'GSM T4.2026'!F:F)} -> #N/A | C15: {=XLOOKUP(E15,Sheet6!H:H,Sheet6!G:G)} -> CLN | D15: {=XLOOKUP(E15,'GSM T4.2026'!D:D,#REF!)} -> #N/A | E15: KFM_HCM_Q06 - 126 Chợ Lớn - MINI | F15: 45929 | G15: =F15-3 -> 45926 | H15: =F15-5 -> 45924 | I15: 22/09 - 02/10 | J15: X | K15: DONE | T15: 45935 | U15: 20/05/2025
A16: =ROW()-9 -> 7 | B16: {=XLOOKUP(E16,'GSM T4.2026'!D:D,'GSM T4.2026'!F:F)} -> #N/A | C16: {=XLOOKUP(E16,Sheet6!H:H,Sheet6!G:G)} -> PHI | D16: {=XLOOKUP(E16,'GSM T4.2026'!D:D,#REF!)} -> #N/A | E16: KFM_HCM_GVA - 410 Phan Huy Ích - MART | F16: 45994 | G16: =F16-3 -> 45991 | H16: =F16-5 -> 45989 | I16: 30/11 - 7/12 | J16: X | K16: DONE | M16: BÀN GIAO KHU VỰC GSM T11 | T16: 21//11/2025 | U16: 30/11/2025
A17: =ROW()-9 -> 8 | B17: {=XLOOKUP(E17,'GSM T4.2026'!D:D,'GSM T4.2026'!F:F)} -> #N/A | C17: {=XLOOKUP(E17,Sheet6!H:H,Sheet6!G:G)} -> NVQ | D17: {=XLOOKUP(E17,'GSM T4.2026'!D:D,#REF!)} -> #N/A | E17: KFM_HCM_Q12 - 678 Nguyễn Văn Quá - MART | F17: 45995 | G17: =F17-3 -> 45992 | H17: =F17-5 -> 45990 | I17: 1/12 - 7/12 | J17: X | K17: DONE | M17: KK BÀN GIAO = KK TỔNG | T17: 45937 | U17: 20/07/2025
A18: =ROW()-9 -> 9 | B18: {=XLOOKUP(E18,'GSM T4.2026'!D:D,'GSM T4.2026'!F:F)} -> #N/A | C18: A115 | D18: {=XLOOKUP(E18,'GSM T4.2026'!D:D,#REF!)} -> #N/A | E18: KFM_HCM_BTH - 484B Lê Quang Định - MINI | F18: 45995 | G18: =F18-3 -> 45992 | H18: =F18-5 -> 45990 | I18: 30/11 - 07/12 | J18: X | K18: DONE | M18: Gsm đề xuất | T18: 20/10/2025 | U18: 26/10/2025
A19: =ROW()-9 -> 10 | B19: {=XLOOKUP(E19,'GSM T4.2026'!D:D,'GSM T4.2026'!F:F)} -> #N/A | C19: A111 | D19: {=XLOOKUP(E19,'GSM T4.2026'!D:D,#REF!)} -> #N/A | E19: KFM_HCM_TDU - BA-S03 New City - MINI | F19: 45995 | G19: =F19-3 -> 45992 | H19: =F19-5 -> 45990 | I19: 27/11 - 05/12 | J19: X | K19: DONE | M19: Gsm đề xuất | T19: 46002 | U19: 20/11/2025
A20: =ROW()-9 -> 11 | B20: {=XLOOKUP(E20,'GSM T4.2026'!D:D,'GSM T4.2026'!F:F)} -> #N/A | C20: {=XLOOKUP(E20,Sheet6!H:H,Sheet6!G:G)} -> ECG | D20: {=XLOOKUP(E20,'GSM T4.2026'!D:D,#REF!)} -> #N/A | E20: KFM_HCM_Q07 - SH16 Eco Green - MINI | F20: 45996 | G20: =F20-3 -> 45993 | H20: =F20-5 -> 45991 | I20: 1/12 - 7//12 | J20: X | K20: DONE | L20: 45700 | M20: KK BÀN GIAO = KK TỔNG | N20: 45996 | O20: 45996 | P20: 45996 | Q20: 45996 | R20: 45905 | S20: 45935 | T20: 15/10/2025 | U20: 23/10/2025
A21: =ROW()-9 -> 12 | B21: {=XLOOKUP(E21,'GSM T4.2026'!D:D,'GSM T4.2026'!F:F)} -> #N/A | C21: A112 | D21: {=XLOOKUP(E21,'GSM T4.2026'!D:D,#REF!)} -> #N/A | E21: KFM_HCM_Q01 - 93 Cô Giang - MINI | F21: 45996 | G21: =F21-3 -> 45993 | H21: =F21-5 -> 45991 | I21: 01/12 -10/12 | J21: X | K21: DONE | M21: Gsm đề xuất
A22: =ROW()-9 -> 13 | B22: {=XLOOKUP(E22,'GSM T4.2026'!D:D,'GSM T4.2026'!F:F)} -> #N/A | C22: {=XLOOKUP(E22,Sheet6!H:H,Sheet6!G:G)} -> SCV | D22: {=XLOOKUP(E22,'GSM T4.2026'!D:D,#REF!)} -> #N/A | E22: KFM_HCM_Q07 - B0.02 Scenic Valley 2 - MINI | F22: 46002 | G22: =F22-3 -> 45999 | H22: =F22-5 -> 45997 | I22: 7/12 - 14/12 | J22: X | K22: DONE | M22: KK BÀN GIAO = KK TỔNG
A23: =ROW()-9 -> 14 | B23: {=XLOOKUP(E23,'GSM T4.2026'!D:D,'GSM T4.2026'!F:F)} -> #N/A | C23: {=XLOOKUP(E23,Sheet6!H:H,Sheet6!G:G)} -> NKM | D23: {=XLOOKUP(E23,'GSM T4.2026'!D:D,#REF!)} -> #N/A | E23: KFM_HCM_GVA - 371 Nguyễn Kiệm - MINI | F23: 46006 | G23: =F23-3 -> 46003 | H23: =F23-5 -> 46001 | I23: 09/12 - 18/12 | J23: X | K23: DONE | M23: KK BÀN GIAO = KK TỔNG | T23: 45819 | U23: 13/11/2025
A24: =ROW()-9 -> 15 | B24: {=XLOOKUP(E24,'GSM T4.2026'!D:D,'GSM T4.2026'!F:F)} -> #N/A | C24: A110 | D24: {=XLOOKUP(E24,'GSM T4.2026'!D:D,#REF!)} -> #N/A | E24: KFM_HCM_Q10 - Jasmine 1 Hà Đô Centrosa - MART | F24: 46006 | G24: =F24-3 -> 46003 | H24: =F24-5 -> 46001 | I24: 10/12 - 20/12 | J24: X | K24: DONE | M24: Gsm đề xuất
A25: =ROW()-9 -> 16 | B25: {=XLOOKUP(E25,'GSM T4.2026'!D:D,'GSM T4.2026'!F:F)} -> #N/A | C25: A121 | D25: {=XLOOKUP(E25,'GSM T4.2026'!D:D,#REF!)} -> #N/A | E25: KFM_HCM_Q06 - 123 Lý Chiêu Hoàng - MINI | F25: 46006 | G25: =F25-3 -> 46003 | H25: =F25-5 -> 46001 | I25: 11/12 - 18/12 | J25: X | K25: DONE | M25: Gsm đề xuất
A26: =ROW()-9 -> 17 | B26: {=XLOOKUP(E26,'GSM T4.2026'!D:D,'GSM T4.2026'!F:F)} -> #N/A | C26: A124 | D26: {=XLOOKUP(E26,'GSM T4.2026'!D:D,#REF!)} -> #N/A | E26: KFM_HCM_TDU - 74 Đường Số 1 Chung Cư Sky 9 - MINI | F26: 46007 | G26: =F26-3 -> 46004 | H26: =F26-5 -> 46002 | I26: 10/12 - 22/12 | J26: X | K26: DONE | M26: Gsm đề xuất
A27: =ROW()-9 -> 18 | B27: {=XLOOKUP(E27,'GSM T4.2026'!D:D,'GSM T4.2026'!F:F)} -> #N/A | C27: A116 | D27: {=XLOOKUP(E27,'GSM T4.2026'!D:D,#REF!)} -> #N/A | E27: KFM_HCM_Q12 - 76 Trần Thị Cờ - MINI | F27: 46008 | G27: =F27-3 -> 46005 | H27: =F27-5 -> 46003 | I27: 14/12 - 21/12 | J27: X | K27: DONE | M27: Gsm đề xuất
A28: =ROW()-9 -> 19 | B28: {=XLOOKUP(E28,'GSM T4.2026'!D:D,'GSM T4.2026'!F:F)} -> #N/A | C28: A117 | D28: {=XLOOKUP(E28,'GSM T4.2026'!D:D,#REF!)} -> #N/A | E28: KFM_BDU_TAN - SH14 The Rivana - MINI | F28: 46009 | G28: =F28-3 -> 46006 | H28: =F28-5 -> 46004 | I28: 13/12 - 20/12 | J28: X | K28: DONE | M28: Gsm đề xuất
A29: =ROW()-9 -> 20 | B29: {=XLOOKUP(E29,'GSM T4.2026'!D:D,'GSM T4.2026'!F:F)} -> #N/A | C29: A125 | D29: {=XLOOKUP(E29,'GSM T4.2026'!D:D,#REF!)} -> #N/A | E29: KFM_HCM_TDU - 115 Man Thiện - MINI | F29: 46009 | G29: =F29-3 -> 46006 | H29: =F29-5 -> 46004 | I29: 13/12 - 20/12 | J29: X | K29: DONE | M29: Gsm đề xuất
A30: =ROW()-9 -> 21 | B30: {=XLOOKUP(E30,'GSM T4.2026'!D:D,'GSM T4.2026'!F:F)} -> #N/A | C30: {=XLOOKUP(E30,Sheet6!H:H,Sheet6!G:G)} -> A103 | D30: {=XLOOKUP(E30,'GSM T4.2026'!D:D,#REF!)} -> #N/A | E30: KFM_HCM_NBE - 222 Lê Văn Lương - MINI | F30: 46014 | G30: =F30-3 -> 46011 | H30: =F30-5 -> 46009 | I30: 20/12/2025 - 27/12/2025 | J30: X | K30: DONE | M30: Gsm đề xuất
A31: =ROW()-9 -> 22 | B31: {=XLOOKUP(E31,'GSM T4.2026'!D:D,'GSM T4.2026'!F:F)} -> #N/A | C31: A113 | D31: {=XLOOKUP(E31,'GSM T4.2026'!D:D,#REF!)} -> #N/A | E31: KFM_HCM_BTH - 216 Phan Văn Hân - MINI | F31: 46019 | G31: =F31-3 -> 46016 | H31: =F31-5 -> 46014 | I31: 24/12 - 31/12 | J31: X | K31: DONE | M31: Gsm đề xuất
A32: =ROW()-9 -> 23 | B32: {=XLOOKUP(E32,'GSM T4.2026'!D:D,'GSM T4.2026'!F:F)} -> #N/A | C32: A118 | D32: {=XLOOKUP(E32,'GSM T4.2026'!D:D,#REF!)} -> #N/A | E32: KFM_HCM_Q10 - 74 Vĩnh Viễn - MINI | F32: 46019 | G32: =F32-3 -> 46016 | H32: =F32-5 -> 46014 | I32: 24/12 - 31/12 | J32: X | K32: DONE | M32: Gsm đề xuất
A33: =ROW()-9 -> 24 | B33: {=XLOOKUP(E33,'GSM T4.2026'!D:D,'GSM T4.2026'!F:F)} -> #N/A | C33: A126 | D33: {=XLOOKUP(E33,'GSM T4.2026'!D:D,#REF!)} -> #N/A | E33: KFM_HCM_Q03 - 274 Lê Văn Sỹ - MINI | F33: 46020 | G33: =F33-3 -> 46017 | H33: =F33-5 -> 46015 | I33: 24/12/2025 - 31/12/2025 | J33: X | K33: DONE | M33: Gsm đề xuất
A34: =ROW()-9 -> 25 | B34: {=XLOOKUP(E34,'GSM T4.2026'!D:D,'GSM T4.2026'!F:F)} -> #N/A | C34: A123 | D34: {=XLOOKUP(E34,'GSM T4.2026'!D:D,#REF!)} -> #N/A | E34: KFM_HCM_TDU - 29B Đường Số 30 4S Linh Đông - MINI | F34: 46018 | G34: =F34-3 -> 46015 | H34: =F34-5 -> 46013 | I34: 22/12/2025 - 31/12/2025 | J34: X | K34: DONE | L34: Không KK TỔNG | M34: Gsm đề xuất
A35: =ROW()-9 -> 26 | B35: {=XLOOKUP(E35,'GSM T4.2026'!D:D,'GSM T4.2026'!F:F)} -> #N/A | C35: A119 | D35: {=XLOOKUP(E35,'GSM T4.2026'!D:D,#REF!)} -> #N/A | E35: KFM_HCM_TDU - 09 Đào Trinh Nhất - MINI | F35: 46020 | G35: =F35-3 -> 46017 | H35: =F35-5 -> 46015 | I35: 22/12/2025 - 31/12/2025 | J35: X | K35: DONE | M35: Gsm đề xuất
A36: =ROW()-9 -> 27 | B36: {=XLOOKUP(E36,'GSM T4.2026'!D:D,'GSM T4.2026'!F:F)} -> #N/A | C36: A128 | D36: {=XLOOKUP(E36,'GSM T4.2026'!D:D,#REF!)} -> #N/A | E36: KFM_HCM_GVA - TM0.03 CH3 Cityland Park Hill - MINI | F36: 46019 | G36: =F36-3 -> 46016 | H36: =F36-5 -> 46014 | I36: 24/12 - 31/12 | J36: X | K36: DONE | L36: Không KK TỔNG | M36: Gsm đề xuất
A37: =ROW()-9 -> 28 | B37: {=XLOOKUP(E37,'GSM T4.2026'!D:D,'GSM T4.2026'!F:F)} -> #N/A | C37: A127 | D37: {=XLOOKUP(E37,'GSM T4.2026'!D:D,#REF!)} -> #N/A | E37: KFM_HCM_TDU - B-SH.06 Urban Green - MINI | F37: 46020 | G37: =F37-3 -> 46017 | H37: =F37-5 -> 46015 | I37: 22/12/2025 - 31/12/2025 | J37: X | K37: DONE | L37: Không KK TỔNG | M37: Gsm đề xuất
A38: =ROW()-9 -> 29 | B38: {=XLOOKUP(E38,'GSM T4.2026'!D:D,'GSM T4.2026'!F:F)} -> #N/A | C38: A132 | D38: {=XLOOKUP(E38,'GSM T4.2026'!D:D,#REF!)} -> #N/A | E38: KFM_HCM_TDU - 136 Hiệp Bình - MINI | F38: 46016 | G38: =F38-3 -> 46013 | H38: =F38-5 -> 46011 | I38: 22/12/2025 - 31/12/2025 | J38: X | K38: DONE | L38: Không KK TỔNG | M38: Gsm đề xuất
A39: =ROW()-9 -> 30 | B39: {=XLOOKUP(E39,'GSM T4.2026'!D:D,'GSM T4.2026'!F:F)} -> #N/A | C39: {=XLOOKUP(E39,Sheet6!H:H,Sheet6!G:G)} -> ERT | D39: {=XLOOKUP(E39,'GSM T4.2026'!D:D,#REF!)} -> #N/A | E39: KFM_HCM_Q07 - 0105 B4 Era Town - MART | G39: =F39-3 -> -3 | H39: =F39-5 -> -5 | K39: NGƯNG KIỂM KÊ | N39: 25/02/2025 | O39: 25/02/2025 | P39: 26/02/2025 | Q39: 27/02/2025 | R39: 24/02/2025
A40: =ROW()-9 -> 31 | B40: {=XLOOKUP(E40,'GSM T4.2026'!D:D,'GSM T4.2026'!F:F)} -> #N/A | C40: {=XLOOKUP(E40,Sheet6!H:H,Sheet6!G:G)} -> HTN | D40: {=XLOOKUP(E40,'GSM T4.2026'!D:D,#REF!)} -> #N/A | E40: KFM_HCM_TDU - 17 Hồ Thị Nhung - MINI | F40: 45753 | G40: =F40-3 -> 45750 | H40: =F40-5 -> 45748 | I40: 31/03 - 09/04 | J40: X | K40: DONE
...

Sheet Lịch Kiểm kê 2026
F1: LỊCH KIỂM KÊ TỔNG 2026 | L1: GSM Báo đổi
F2: Thời gian: | L2: Thay đổi 7-10 ngày hiện tại => mới điều chỉnh kịp
C3: SDT IT hỗ trợ khi ST gặp sự cố trong lúc kiểm kê | F3: Ngô Quang Cẩm Tú | I3: 0386446113 | P3: DONE
F4: Hoàng Ngọc Long | I4: 0981683801
F5: Tô Thanh Vinh | I5: 0877410295
F6: Nguyễn Thanh Tùng | I6: 0367910431
F7: Nguyễn Xuân Hoánh | I7: 0886485610
L8: SOC | Q8: Dành cho các ST đã thực hiện kiểm kê bàn giao full 5 ngành hàng => điền ngày đã kiểm kê tương ứng vào bên dưới
A9: STT | B9: OPENNING | C9: GSM | D9: ID Mart | E9: KV | F9: Tên Siêu thị | G9: Ngày kiểm kê tổng 2025 | H9: Số ngày đã KK Tổng | I9: Ngày kiểm kê tổng 2026 | J9: Ngày kiểm Fresh food | K9: Ngày đổ phiếu tổng | L9: Ngưng kiểm kê Daily | M9: Đã cài lịch kiểm kê | N9: NGÀY KIỂM KÊ TÀI SẢN , VPP , CCDC | O9: Số ngày đến ngày đổ phiếu tổng | P9: Note | Q9: 1.BAKERY AND DELICA | R9: 1.CHILLED AND FROZEN | S9: 1.DAIRY AND ICE CREAM | T9: 1.FMCG | U9: 1.FRESH FOOD | V9: Ngày kiểm Fresh food thực tê | W9: Bắt đầu Ngưng Kiểm kê Daily | X9: Kết Thúc Ngưng Kiểm kê Daily | Y9: Tháng | Z9: Note
A10: =ROW()-9 -> 1 | B10: {=XLOOKUP(D10,'GSM T4.2026'!$B$1:$B$996,'GSM T4.2026'!$C$1:$C$996)} -> 31/05/2025 | C10: {=XLOOKUP(F10,'GSM T4.2026'!D:D,'GSM T4.2026'!F:F)} -> Nguyễn Thị Ngọc Bích | D10: {=XLOOKUP(F10,'GSM T4.2026'!$D:$D,'GSM T4.2026'!$B:$B)} -> VH7 | E10: {=XLOOKUP(F10,'GSM T4.2026'!D:D,'GSM T4.2026'!$E:$E)} -> HCM 005 | F10: KFM_HCM_TDU - BS11 Vinhomes Grand Park | G10: 45988 | H10: =TODAY()-G10 -> 182 | I10: 46037 | J10: =I10-2 -> 46035 | K10: =I10-4 -> 46033 | L10: 11/01/2026 - 19/01/2026 | M10: DONE | O10: =if(K10-TODAY()<0,0,K10-today()) -> 0 | P10: KK TỔNG BÀN GIAO | Y10: =MONTH(I10) -> 1
A11: =ROW()-9 -> 2 | B11: {=XLOOKUP(D11,'GSM T4.2026'!$B$1:$B$996,'GSM T4.2026'!$C$1:$C$996)} -> 22/03/2025 | C11: {=XLOOKUP(F11,'GSM T4.2026'!D:D,'GSM T4.2026'!F:F)} -> Lê Nguyễn Ngọc Phượng | D11: {=XLOOKUP(F11,'GSM T4.2026'!$D:$D,'GSM T4.2026'!$B:$B)} -> KDG | E11: {=XLOOKUP(F11,'GSM T4.2026'!D:D,'GSM T4.2026'!$E:$E)} -> HCM 016 | F11: KFM_HCM_Q03 - 10D Kỳ Đồng | G11: 45984 | H11: =TODAY()-G11 -> 186 | I11: 46041 | J11: =I11-2 -> 46039 | K11: =I11-4 -> 46037 | L11: 15/01/2026 - 22/01/2026 | M11: DONE | O11: =if(K11-TODAY()<0,0,K11-today()) -> 0 | P11: KK TỔNG BÀN GIAO | Y11: =MONTH(I11) -> 1
A12: =ROW()-9 -> 3 | B12: {=XLOOKUP(D12,'GSM T4.2026'!$B$1:$B$996,'GSM T4.2026'!$C$1:$C$996)} -> 45905 | C12: {=XLOOKUP(F12,'GSM T4.2026'!D:D,'GSM T4.2026'!F:F)} -> Trần Hữu Vinh | D12: {=XLOOKUP(F12,'GSM T4.2026'!$D:$D,'GSM T4.2026'!$B:$B)} -> NTN | E12: {=XLOOKUP(F12,'GSM T4.2026'!D:D,'GSM T4.2026'!$E:$E)} -> HCM 015 | F12: KFM_HCM_PNH - 154 Nguyễn Trọng Tuyển | G12: 45951 | H12: =TODAY()-G12 -> 219 | I12: 46041 | J12: =I12-2 -> 46039 | K12: =I12-4 -> 46037 | L12: 15/01/2026 - 22/01/2026 | M12: DONE | O12: =if(K12-TODAY()<0,0,K12-today()) -> 0 | P12: KK TỔNG BÀN GIAO | Y12: =MONTH(I12) -> 1
A13: =ROW()-9 -> 4 | B13: {=XLOOKUP(D13,'GSM T4.2026'!$B$1:$B$996,'GSM T4.2026'!$C$1:$C$996)} -> 14/10/2023 | C13: {=XLOOKUP(F13,'GSM T4.2026'!D:D,'GSM T4.2026'!F:F)} -> Hồng Trọng Nghĩa | D13: {=XLOOKUP(F13,'GSM T4.2026'!$D:$D,'GSM T4.2026'!$B:$B)} -> MZK | E13: {=XLOOKUP(F13,'GSM T4.2026'!D:D,'GSM T4.2026'!$E:$E)} -> HCM 022 | F13: KFM_HCM_BCH - TMDV2 Mizuki Park | G13: 45790 | H13: =TODAY()-G13 -> 380 | I13: 46044 | J13: =I13-2 -> 46042 | K13: =I13-4 -> 46040 | L13: 18/01/2026 - 25/01/2026 | M13: DONE | O13: =if(K13-TODAY()<0,0,K13-today()) -> 0 | P13: KK TỔNG BÀN GIAO | Y13: =MONTH(I13) -> 1
A14: =ROW()-9 -> 5 | B14: {=XLOOKUP(D14,'GSM T4.2026'!$B$1:$B$996,'GSM T4.2026'!$C$1:$C$996)} -> 27/06/2025 | C14: {=XLOOKUP(F14,'GSM T4.2026'!D:D,'GSM T4.2026'!F:F)} -> Hứa Thái Hiển | D14: {=XLOOKUP(F14,'GSM T4.2026'!$D:$D,'GSM T4.2026'!$B:$B)} -> A104 | E14: {=XLOOKUP(F14,'GSM T4.2026'!D:D,'GSM T4.2026'!$E:$E)} -> HCM 023 | F14: KFM_HCM_NBE - 5/3D Huỳnh Tấn Phát | G14: 45950 | H14: =TODAY()-G14 -> 220 | I14: 46044 | J14: =I14-2 -> 46042 | K14: =I14-4 -> 46040 | L14: 19/01/2026 - 25/01/2026 | M14: DONE | O14: =if(K14-TODAY()<0,0,K14-today()) -> 0 | P14: KK TỔNG BÀN GIAO | Y14: =MONTH(I14) -> 1
A15: =ROW()-9 -> 6 | B15: {=XLOOKUP(D15,'GSM T4.2026'!$B$1:$B$996,'GSM T4.2026'!$C$1:$C$996)} -> 45605 | C15: {=XLOOKUP(F15,'GSM T4.2026'!D:D,'GSM T4.2026'!F:F)} -> Nguyễn Thị Ngọc Bích | D15: {=XLOOKUP(F15,'GSM T4.2026'!$D:$D,'GSM T4.2026'!$B:$B)} -> VH5 | E15: {=XLOOKUP(F15,'GSM T4.2026'!D:D,'GSM T4.2026'!$E:$E)} -> HCM 005 | F15: KFM_HCM_TDU - S03.05 Vinhomes Grand Park | G15: 45796 | H15: =TODAY()-G15 -> 374 | I15: 46050 | J15: =I15-2 -> 46048 | K15: =I15-4 -> 46046 | L15: 24/01/2026 - 31/01/2026 | M15: DONE | O15: =if(K15-TODAY()<0,0,K15-today()) -> 0 | P15: KK TỔNG BÀN GIAO | Y15: =MONTH(I15) -> 1
A16: =ROW()-9 -> 7 | B16: {=XLOOKUP(D16,'GSM T4.2026'!$B$1:$B$996,'GSM T4.2026'!$C$1:$C$996)} -> 15/11/2025 | C16: {=XLOOKUP(F16,'GSM T4.2026'!D:D,'GSM T4.2026'!F:F)} -> Hồ Xuân Thịnh | D16: {=XLOOKUP(F16,'GSM T4.2026'!$D:$D,'GSM T4.2026'!$B:$B)} -> A125 | E16: {=XLOOKUP(F16,'GSM T4.2026'!D:D,'GSM T4.2026'!$E:$E)} -> HCM 021 | F16: KFM_HCM_TDU - 115 Man Thiện | G16: 46009 | H16: =TODAY()-G16 -> 161 | I16: 46052 | J16: =I16-2 -> 46050 | K16: =I16-4 -> 46048 | L16: 26/01/2026 - 02/02/2026 | M16: DONE | O16: =if(K16-TODAY()<0,0,K16-today()) -> 0 | P16: KK TỔNG BÀN GIAO | Y16: =MONTH(I16) -> 1
A17: =ROW()-9 -> 8 | B17: {=XLOOKUP(D17,'GSM T4.2026'!$B$1:$B$996,'GSM T4.2026'!$C$1:$C$996)} -> 45386 | C17: {=XLOOKUP(F17,'GSM T4.2026'!D:D,'GSM T4.2026'!F:F)} -> Phạm Duy | D17: {=XLOOKUP(F17,'GSM T4.2026'!$D:$D,'GSM T4.2026'!$B:$B)} -> PTN | E17: {=XLOOKUP(F17,'GSM T4.2026'!D:D,'GSM T4.2026'!$E:$E)} -> HCM 024 | F17: KFM_HCM_Q07 - E72 Phú Thuận | G17: 45908 | H17: =TODAY()-G17 -> 262 | I17: 46090 | J17: =I17-2 -> 46088 | K17: =I17-4 -> 46086 | L17: 06/03/2026 - 11/03/2026 | M17: DONE | N17: 46329 | O17: =if(K17-TODAY()<0,0,K17-today()) -> 0 | P17: KK TỔNG BÀN GIAO SM | Y17: =MONTH(I17) -> 3
A18: =ROW()-9 -> 9 | B18: {=XLOOKUP(D18,'GSM T4.2026'!$B$1:$B$996,'GSM T4.2026'!$C$1:$C$996)} -> 24/05/2024 | C18: {=XLOOKUP(F18,'GSM T4.2026'!D:D,'GSM T4.2026'!F:F)} -> Võ Minh Đạt | D18: {=XLOOKUP(F18,'GSM T4.2026'!$D:$D,'GSM T4.2026'!$B:$B)} -> QHG | E18: {=XLOOKUP(F18,'GSM T4.2026'!D:D,'GSM T4.2026'!$E:$E)} -> HCM 018 | F18: KFM_HCM_TDU - 59 Quốc Hương | G18: 45764 | H18: =TODAY()-G18 -> 406 | I18: 46145 | J18: =I18+2 -> 46147 | K18: =I18-3 -> 46142 | L18: 02/05/2026 - 07/05/2026 | M18: DONE | N18: 46208 | O18: =if(K18-TODAY()<0,0,K18-today()) -> 0 | P18: KK TỔNG BÀN GIAO SM | Y18: =MONTH(I18) -> 5
A19: =ROW()-9 -> 10 | B19: {=XLOOKUP(D19,'GSM T4.2026'!$B$1:$B$996,'GSM T4.2026'!$C$1:$C$996)} -> 45912 | C19: {=XLOOKUP(F19,'GSM T4.2026'!D:D,'GSM T4.2026'!F:F)} -> Võ Thị Thùy Dương | D19: {=XLOOKUP(F19,'GSM T4.2026'!$D:$D,'GSM T4.2026'!$B:$B)} -> A110 | E19: {=XLOOKUP(F19,'GSM T4.2026'!D:D,'GSM T4.2026'!$E:$E)} -> HCM 032 | F19: KFM_HCM_Q10 - Jasmine 1 Hà Đô Centrosa | G19: 46006 | H19: =TODAY()-G19 -> 164 | I19: 46080 | J19: =I19-2 -> 46078 | K19: =I19-4 -> 46076 | L19: 24/02/2026 - 28/02/2026 | M19: DONE | N19: 46056 | O19: =if(K19-TODAY()<0,0,K19-today()) -> 0 | P19: KK TỔNG BÀN GIAO | Y19: =MONTH(I19) -> 2
A20: =ROW()-9 -> 11 | B20: {=XLOOKUP(D20,'GSM T4.2026'!$B$1:$B$996,'GSM T4.2026'!$C$1:$C$996)} -> 27/12/2025 | C20: {=XLOOKUP(F20,'GSM T4.2026'!D:D,'GSM T4.2026'!F:F)} -> Trương Công Nhật Tùng | D20: {=XLOOKUP(F20,'GSM T4.2026'!$D:$D,'GSM T4.2026'!$B:$B)} -> A141 | E20: {=XLOOKUP(F20,'GSM T4.2026'!D:D,'GSM T4.2026'!$E:$E)} -> HCM 030 | F20: KFM_HCM_Q07 - X1.013 Sunrise City North | G20: NSO | H20: NSO | I20: 46094 | J20: =I20-2 -> 46092 | K20: =I20-4 -> 46090 | L20: 10/03/2026 - 15/03/2026 | M20: DONE | N20: 15/03/2026 | O20: =if(K20-TODAY()<0,0,K20-today()) -> 0 | P20: KK TỔNG BÀN GIAO SM | Y20: =MONTH(I20) -> 3
A21: =ROW()-9 -> 12 | B21: {=XLOOKUP(D21,'GSM T4.2026'!$B$1:$B$996,'GSM T4.2026'!$C$1:$C$996)} -> 45780 | C21: {=XLOOKUP(F21,'GSM T4.2026'!D:D,'GSM T4.2026'!F:F)} -> Lê Ngọc Phát | D21: {=XLOOKUP(F21,'GSM T4.2026'!$D:$D,'GSM T4.2026'!$B:$B)} -> A101 | E21: {=XLOOKUP(F21,'GSM T4.2026'!D:D,'GSM T4.2026'!$E:$E)} -> HCM 027 | F21: KFM_BDU_DAN - 27 Tân Lập | G21: 45946 | H21: =TODAY()-G21 -> 224 | I21: 46100 | J21: =I21-2 -> 46098 | K21: =I21-3 -> 46097 | L21: 16/03/2026 - 22/03/2026 | M21: DONE | O21: =if(K21-TODAY()<0,0,K21-today()) -> 0 | P21: KIỂM TỔNG 2026 | Y21: =MONTH(I21) -> 3
A22: =ROW()-9 -> 13 | B22: {=XLOOKUP(D22,'GSM T4.2026'!$B$1:$B$996,'GSM T4.2026'!$C$1:$C$996)} -> 15/07/2023 | C22: {=XLOOKUP(F22,'GSM T4.2026'!D:D,'GSM T4.2026'!F:F)} -> Nguyễn Đình Vũ | D22: {=XLOOKUP(F22,'GSM T4.2026'!$D:$D,'GSM T4.2026'!$B:$B)} -> DXH | E22: {=XLOOKUP(F22,'GSM T4.2026'!D:D,'GSM T4.2026'!$E:$E)} -> HCM 006 | F22: KFM_HCM_TDU - 539 Đỗ Xuân Hợp | G22: 45766 | H22: =TODAY()-G22 -> 404 | I22: 46102 | J22: =I22-2 -> 46100 | K22: =I22-3 -> 46099 | L22: 18/03/2026 - 24/03/2026 | M22: DONE | N22: 22/03/2026 | O22: =if(K22-TODAY()<0,0,K22-today()) -> 0 | P22: KK TỔNG BÀN GIAO SM | Y22: =MONTH(I22) -> 3
A23: =ROW()-9 -> 14 | B23: {=XLOOKUP(D23,'GSM T4.2026'!$B$1:$B$996,'GSM T4.2026'!$C$1:$C$996)} -> 23/03/2023 | C23: {=XLOOKUP(F23,'GSM T4.2026'!D:D,'GSM T4.2026'!F:F)} -> Phạm Hữu Chương | D23: {=XLOOKUP(F23,'GSM T4.2026'!$D:$D,'GSM T4.2026'!$B:$B)} -> NTD | E23: {=XLOOKUP(F23,'GSM T4.2026'!D:D,'GSM T4.2026'!$E:$E)} -> HCM 020 | F23: KFM_HCM_TDU - 160A Nguyễn Thị Định | G23: 45753 | H23: =TODAY()-G23 -> 417 | I23: 46102 | J23: =I23-2 -> 46100 | K23: =I23-3 -> 46099 | L23: 18/03/2026 - 24/03/2026 | M23: DONE | N23: 22/03/2026 | O23: =if(K23-TODAY()<0,0,K23-today()) -> 0 | P23: KK TỔNG BÀN GIAO SM | Y23: =MONTH(I23) -> 3
A24: =ROW()-9 -> 15 | B24: {=XLOOKUP(D24,'GSM T4.2026'!$B$1:$B$996,'GSM T4.2026'!$C$1:$C$996)} -> 14/10/2023 | C24: {=XLOOKUP(F24,'GSM T4.2026'!D:D,'GSM T4.2026'!F:F)} -> Hồ Xuân Thịnh | D24: {=XLOOKUP(F24,'GSM T4.2026'!$D:$D,'GSM T4.2026'!$B:$B)} -> VH2 | E24: {=XLOOKUP(F24,'GSM T4.2026'!D:D,'GSM T4.2026'!$E:$E)} -> HCM 021 | F24: KFM_HCM_TDU - S10.02 Vinhomes Grand Park | G24: 45966 | H24: =TODAY()-G24 -> 204 | I24: 46107 | J24: =I24-3 -> 46104 | K24: =I24-4 -> 46103 | L24: 22/03/2026 – 29/03/2026 | M24: DONE | N24: 30/03/2026 | O24: =if(K24-TODAY()<0,0,K24-today()) -> 0 | P24: KK TỔNG BÀN GIAO SM | Y24: =MONTH(I24) -> 3
A25: =ROW()-9 -> 16 | B25: {=XLOOKUP(D25,'GSM T4.2026'!$B$1:$B$996,'GSM T4.2026'!$C$1:$C$996)} -> 45078 | C25: {=XLOOKUP(F25,'GSM T4.2026'!D:D,'GSM T4.2026'!F:F)} -> Đặng Đăng Khoa | D25: {=XLOOKUP(F25,'GSM T4.2026'!$D:$D,'GSM T4.2026'!$B:$B)} -> NVQ | E25: {=XLOOKUP(F25,'GSM T4.2026'!D:D,'GSM T4.2026'!$E:$E)} -> HCM 036 | F25: KFM_HCM_Q12 - 678 Nguyễn Văn Quá | G25: 45995 | H25: =TODAY()-G25 -> 175 | I25: 46107 | J25: =I25-2 -> 46105 | K25: =I25-3 -> 46104 | L25: 23/03/2026 – 29/03/2026 | M25: DONE | N25: 28/03/2026 | O25: =if(K25-TODAY()<0,0,K25-today()) -> 0 | P25: KK TỔNG BÀN GIAO SM | Y25: =MONTH(I25) -> 3
A26: =ROW()-9 -> 17 | B26: {=XLOOKUP(D26,'GSM T4.2026'!$B$1:$B$996,'GSM T4.2026'!$C$1:$C$996)} -> 45233 | C26: {=XLOOKUP(F26,'GSM T4.2026'!D:D,'GSM T4.2026'!F:F)} -> Nguyễn Thị Ngọc Giàu | D26: {=XLOOKUP(F26,'GSM T4.2026'!$D:$D,'GSM T4.2026'!$B:$B)} -> DS7 | E26: {=XLOOKUP(F26,'GSM T4.2026'!D:D,'GSM T4.2026'!$E:$E)} -> HCM 031 | F26: KFM_HCM_BTA - 99 Đường Số 7 | G26: 45964 | H26: =TODAY()-G26 -> 206 | I26: 46107 | J26: =I26-2 -> 46105 | K26: =I26-3 -> 46104 | L26: 23/03/2026 - 31/03/2026 | M26: DONE | N26: 23/03/2026 | O26: =if(K26-TODAY()<0,0,K26-today()) -> 0 | P26: KK TỔNG BÀN GIAO SM | Y26: =MONTH(I26) -> 3
A27: =ROW()-9 -> 18 | B27: {=XLOOKUP(D27,'GSM T4.2026'!$B$1:$B$996,'GSM T4.2026'!$C$1:$C$996)} -> 25/12/2025 | C27: {=XLOOKUP(F27,'GSM T4.2026'!D:D,'GSM T4.2026'!F:F)} -> Nguyễn Thị Ngọc Giàu | D27: {=XLOOKUP(F27,'GSM T4.2026'!$D:$D,'GSM T4.2026'!$B:$B)} -> A139 | E27: {=XLOOKUP(F27,'GSM T4.2026'!D:D,'GSM T4.2026'!$E:$E)} -> HCM 031 | F27: KFM_HCM_BTA - 197 Đường số 1 An Lạc | G27: NSO | H27: NSO | I27: 46108 | J27: =I27-2 -> 46106 | K27: =I27-4 -> 46104 | L27: 23/03/2026 - 30/03/2026 | M27: DONE | N27: 25/03/2026 | O27: =if(K27-TODAY()<0,0,K27-today()) -> 0 | P27: KK TỔNG BÀN GIAO SM | Y27: =MONTH(I27) -> 3
A28: =ROW()-9 -> 19 | B28: {=XLOOKUP(D28,'GSM T4.2026'!$B$1:$B$996,'GSM T4.2026'!$C$1:$C$996)} -> 23/01/2021 | C28: {=XLOOKUP(F28,'GSM T4.2026'!D:D,'GSM T4.2026'!F:F)} -> Huỳnh Thị Tuyết Nhi | D28: {=XLOOKUP(F28,'GSM T4.2026'!$D:$D,'GSM T4.2026'!$B:$B)} -> HTP | E28: {=XLOOKUP(F28,'GSM T4.2026'!D:D,'GSM T4.2026'!$E:$E)} -> HCM 002 | F28: KFM_HCM_Q07 - 571 Huỳnh Tấn Phát | G28: 45967 | H28: =TODAY()-G28 -> 203 | I28: 46109 | J28: =I28-4 -> 46105 | K28: =I28-5 -> 46104 | L28: 23/03/2026 - 31/03/2026 | M28: DONE | N28: 24/03/2026 | O28: =if(K28-TODAY()<0,0,K28-today()) -> 0 | P28: KK TỔNG BÀN GIAO SM | Y28: =MONTH(I28) -> 3
A29: =ROW()-9 -> 20 | B29: {=XLOOKUP(D29,'GSM T4.2026'!$B$1:$B$996,'GSM T4.2026'!$C$1:$C$996)} -> 45933 | C29: {=XLOOKUP(F29,'GSM T4.2026'!D:D,'GSM T4.2026'!F:F)} -> Lê Nguyễn Ngọc Phượng | D29: {=XLOOKUP(F29,'GSM T4.2026'!$D:$D,'GSM T4.2026'!$B:$B)} -> A113 | E29: {=XLOOKUP(F29,'GSM T4.2026'!D:D,'GSM T4.2026'!$E:$E)} -> HCM 016 | F29: KFM_HCM_BTH - 216 Phan Văn Hân | G29: 46019 | H29: =TODAY()-G29 -> 151 | I29: 46109 | J29: =I29-2 -> 46107 | K29: =I29-4 -> 46105 | L29: 23/03/2026 - 31/03/2026 | M29: DONE | N29: 25/03/2026 | O29: =if(K29-TODAY()<0,0,K29-today()) -> 0 | P29: KK TỔNG BÀN GIAO SM | Y29: =MONTH(I29) -> 3
A30: =ROW()-9 -> 21 | B30: {=XLOOKUP(D30,'GSM T4.2026'!$B$1:$B$996,'GSM T4.2026'!$C$1:$C$996)} -> 30/05/2024 | C30: {=XLOOKUP(F30,'GSM T4.2026'!D:D,'GSM T4.2026'!F:F)} -> Võ Minh Đạt | D30: {=XLOOKUP(F30,'GSM T4.2026'!$D:$D,'GSM T4.2026'!$B:$B)} -> NTO | E30: {=XLOOKUP(F30,'GSM T4.2026'!D:D,'GSM T4.2026'!$E:$E)} -> HCM 018 | F30: KFM_HCM_BTH - 108 Ngô Tất Tố | G30: 45755 | H30: =TODAY()-G30 -> 415 | I30: 46110 | J30: =I30-2 -> 46108 | K30: =I30-4 -> 46106 | L30: 25/03/2026 - 31/03/2026 | M30: DONE | N30: 26/03/2026 | O30: =if(K30-TODAY()<0,0,K30-today()) -> 0 | P30: KK TỔNG BÀN GIAO SM | Y30: =MONTH(I30) -> 3
A31: =ROW()-9 -> 22 | B31: {=XLOOKUP(D31,'GSM T4.2026'!$B$1:$B$996,'GSM T4.2026'!$C$1:$C$996)} -> 18/03/2023 | C31: {=XLOOKUP(F31,'GSM T4.2026'!D:D,'GSM T4.2026'!F:F)} -> Đào Hồng Hiện | D31: {=XLOOKUP(F31,'GSM T4.2026'!$D:$D,'GSM T4.2026'!$B:$B)} -> NDT | E31: {=XLOOKUP(F31,'GSM T4.2026'!D:D,'GSM T4.2026'!$E:$E)} -> HCM 035 | F31: KFM_HCM_TDU - 305 Nguyễn Duy Trinh | G31: 45743 | H31: =TODAY()-G31 -> 427 | I31: 46109 | J31: =I31-5 -> 46104 | K31: =I31-2 -> 46107 | L31: 22/03/2026 - 31/03/2026 | M31: DONE | N31: 27/03/2026 | O31: =if(K31-TODAY()<0,0,K31-today()) -> 0 | P31: KK TỔNG BÀN GIAO SM | Y31: =MONTH(I31) -> 3 | Z31: Đổ phiếu tổng lần 2 (27.3)
A32: =ROW()-9 -> 23 | B32: {=XLOOKUP(D32,'GSM T4.2026'!$B$1:$B$996,'GSM T4.2026'!$C$1:$C$996)} -> 19/04/2025 | C32: {=XLOOKUP(F32,'GSM T4.2026'!D:D,'GSM T4.2026'!F:F)} -> Võ Văn Phi Hùng | D32: {=XLOOKUP(F32,'GSM T4.2026'!$D:$D,'GSM T4.2026'!$B:$B)} -> PKD | E32: {=XLOOKUP(F32,'GSM T4.2026'!D:D,'GSM T4.2026'!$E:$E)} -> HCM 029 | F32: KFM_HCM_BTA - TMDV19 Privia Khang Điền | G32: 45971 | H32: =TODAY()-G32 -> 199 | I32: 46110 | J32: =I32-2 -> 46108 | K32: =I32-3 -> 46107 | L32: 25/03/2026 - 31/03/2026 | M32: DONE | N32: 26/03/2026 | O32: =if(K32-TODAY()<0,0,K32-today()) -> 0 | P32: KK TỔNG BÀN GIAO SM | Y32: =MONTH(I32) -> 3
A33: =ROW()-9 -> 24 | B33: {=XLOOKUP(D33,'GSM T4.2026'!$B$1:$B$996,'GSM T4.2026'!$C$1:$C$996)} -> 14/12/2024 | C33: {=XLOOKUP(F33,'GSM T4.2026'!D:D,'GSM T4.2026'!F:F)} -> Phạm Duy | D33: {=XLOOKUP(F33,'GSM T4.2026'!$D:$D,'GSM T4.2026'!$B:$B)} -> Q7R | E33: {=XLOOKUP(F33,'GSM T4.2026'!D:D,'GSM T4.2026'!$E:$E)} -> HCM 024 | F33: KFM_HCM_Q07 - Lô CD L1-12 Q7 Riverside Đào Trí | G33: 45761 | H33: =TODAY()-G33 -> 409 | I33: 46111 | J33: =I33-3 -> 46108 | K33: =I33-4 -> 46107 | L33: 26/03/2026 - 02/04/2026 | M33: DONE | N33: 46026 | O33: =if(K33-TODAY()<0,0,K33-today()) -> 0 | P33: KK TỔNG BÀN GIAO SM | Y33: =MONTH(I33) -> 3
A34: =ROW()-9 -> 25 | B34: {=XLOOKUP(D34,'GSM T4.2026'!$B$1:$B$996,'GSM T4.2026'!$C$1:$C$996)} -> 23/09/2022 | C34: {=XLOOKUP(F34,'GSM T4.2026'!D:D,'GSM T4.2026'!F:F)} -> Lê Huỳnh Thiện | D34: {=XLOOKUP(F34,'GSM T4.2026'!$D:$D,'GSM T4.2026'!$B:$B)} -> PHI | E34: {=XLOOKUP(F34,'GSM T4.2026'!D:D,'GSM T4.2026'!$E:$E)} -> HCM 009 | F34: KFM_HCM_GVA - 410 Phan Huy Ích | G34: 45994 | H34: =TODAY()-G34 -> 176 | I34: 46113 | J34: =I34-2 -> 46111 | K34: =I34-3 -> 46110 | L34: 29/03/2026 – 03/04/2026 | M34: DONE | N34: 29/03/2026 | O34: =if(K34-TODAY()<0,0,K34-today()) -> 0 | P34: KK TỔNG BÀN GIAO SM | Y34: =MONTH(I34) -> 4
A35: =ROW()-9 -> 26 | B35: {=XLOOKUP(D35,'GSM T4.2026'!$B$1:$B$996,'GSM T4.2026'!$C$1:$C$996)} -> 29/03/2025 | C35: {=XLOOKUP(F35,'GSM T4.2026'!D:D,'GSM T4.2026'!F:F)} -> Nguyễn Thị Tuyết Trinh | D35: {=XLOOKUP(F35,'GSM T4.2026'!$D:$D,'GSM T4.2026'!$B:$B)} -> DMR | E35: {=XLOOKUP(F35,'GSM T4.2026'!D:D,'GSM T4.2026'!$E:$E)} -> HCM 011 | F35: KFM_HCM_Q08 - Block C Diamond Riverside | G35: 45971 | H35: =TODAY()-G35 -> 199 | I35: 46115 | J35: =I35-2 -> 46113 | K35: =I35-4 -> 46111 | L35: 30/03/2026 - 06/04/2026 | M35: DONE | N35: 46116 | O35: =if(K35-TODAY()<0,0,K35-today()) -> 0 | P35: KK TỔNG BÀN GIAO SM | Y35: =MONTH(I35) -> 4
A36: =ROW()-9 -> 27 | B36: {=XLOOKUP(D36,'GSM T4.2026'!$B$1:$B$996,'GSM T4.2026'!$C$1:$C$996)} -> 29/07/2022 | C36: {=XLOOKUP(F36,'GSM T4.2026'!D:D,'GSM T4.2026'!F:F)} -> Trương Công Nhật Tùng | D36: {=XLOOKUP(F36,'GSM T4.2026'!$D:$D,'GSM T4.2026'!$B:$B)} -> KHI | E36: {=XLOOKUP(F36,'GSM T4.2026'!D:D,'GSM T4.2026'!$E:$E)} -> HCM 030 | F36: KFM_HCM_Q04 - 98 Khánh Hội | G36: 45966 | H36: =TODAY()-G36 -> 204 | I36: 46115 | J36: =I36-2 -> 46113 | K36: =I36-3 -> 46112 | L36: 31/03/2026 - 06/04/2026 | M36: DONE | N36: 46146 | O36: =if(K36-TODAY()<0,0,K36-today()) -> 0 | P36: KK TỔNG BÀN GIAO SM | Y36: =MONTH(I36) -> 4
A37: =ROW()-9 -> 28 | B37: {=XLOOKUP(D37,'GSM T4.2026'!$B$1:$B$996,'GSM T4.2026'!$C$1:$C$996)} -> 45758 | C37: {=XLOOKUP(F37,'GSM T4.2026'!D:D,'GSM T4.2026'!F:F)} -> Đào Hồng Hiện | D37: {=XLOOKUP(F37,'GSM T4.2026'!$D:$D,'GSM T4.2026'!$B:$B)} -> LVH | E37: {=XLOOKUP(F37,'GSM T4.2026'!D:D,'GSM T4.2026'!$E:$E)} -> HCM 035 | F37: KFM_HCM_TDU - 222 Lê Văn Thịnh | G37: 45831 | H37: =TODAY()-G37 -> 339 | I37: 46115 | J37: =I37-2 -> 46113 | K37: =I37-2 -> 46113 | L37: 31/03/2026 - 06/04/2026 | M37: DONE | N37: 46146 | O37: =if(K37-TODAY()<0,0,K37-today()) -> 0 | P37: KK TỔNG BÀN GIAO SM | Y37: =MONTH(I37) -> 4
A38: =ROW()-9 -> 29 | B38: {=XLOOKUP(D38,'GSM T4.2026'!$B$1:$B$996,'GSM T4.2026'!$C$1:$C$996)} -> 45114 | C38: {=XLOOKUP(F38,'GSM T4.2026'!D:D,'GSM T4.2026'!F:F)} -> Hồng Trọng Nghĩa | D38: {=XLOOKUP(F38,'GSM T4.2026'!$D:$D,'GSM T4.2026'!$B:$B)} -> Q50 | E38: {=XLOOKUP(F38,'GSM T4.2026'!D:D,'GSM T4.2026'!$E:$E)} -> HCM 022 | F38: KFM_HCM_BCH - 511 Quốc lộ 50 | G38: 45952 | H38: =TODAY()-G38 -> 218 | I38: 46116 | J38: =I38-2 -> 46114 | K38: =I38-3 -> 46113 | L38: 01/04/2026 - 06/04/2026 | M38: DONE | N38: 46026 | O38: =if(K38-TODAY()<0,0,K38-today()) -> 0 | P38: KK TỔNG BÀN GIAO SM | Y38: =MONTH(I38) -> 4
A39: =ROW()-9 -> 30 | B39: {=XLOOKUP(D39,'GSM T4.2026'!$B$1:$B$996,'GSM T4.2026'!$C$1:$C$996)} -> 28/12/2024 | C39: {=XLOOKUP(F39,'GSM T4.2026'!D:D,'GSM T4.2026'!F:F)} -> Nguyễn Thị Tuyết Trinh | D39: {=XLOOKUP(F39,'GSM T4.2026'!$D:$D,'GSM T4.2026'!$B:$B)} -> EH3 | E39: {=XLOOKUP(F39,'GSM T4.2026'!D:D,'GSM T4.2026'!$E:$E)} -> HCM 011 | F39: KFM_HCM_BTA - A10-0.02 Ehome 3 | G39: 45784 | H39: =TODAY()-G39 -> 386 | I39: 46146 | J39: =I39-2 -> 46144 | K39: =I39-3 -> 46143 | L39: 01/05/2026 - 07/05/2026 | M39: DONE | N39: 46178 | O39: =if(K39-TODAY()<0,0,K39-today()) -> 0 | P39: KK TỔNG BÀN GIAO SM | Y39: =MONTH(I39) -> 5
A40: =ROW()-9 -> 31 | B40: {=XLOOKUP(D40,'GSM T4.2026'!$B$1:$B$996,'GSM T4.2026'!$C$1:$C$996)} -> 19/01/2024 | C40: {=XLOOKUP(F40,'GSM T4.2026'!D:D,'GSM T4.2026'!F:F)} -> Trần Văn Hiếu | D40: {=XLOOKUP(F40,'GSM T4.2026'!$D:$D,'GSM T4.2026'!$B:$B)} -> VLA | E40: {=XLOOKUP(F40,'GSM T4.2026'!D:D,'GSM T4.2026'!$E:$E)} -> HCM 014 | F40: KFM_HCM_TPH - 128 Vườn Lài | G40: 45795 | H40: =TODAY()-G40 -> 375 | I40: 46116 | J40: =I40-2 -> 46114 | K40: =I40-3 -> 46113 | L40: 01/04/2026 - 07/04/2026 | M40: DONE | N40: 46026 | O40: =if(K40-TODAY()<0,0,K40-today()) -> 0 | P40: KK TỔNG BÀN GIAO SM | Y40: =MONTH(I40) -> 4
...

Sheet GSM T4.2026
A1: STT | B1: Store Code | C1: opening_date | D1: Store Name | E1: GSM Code | F1: GSM Name | J1: Khai Báo hệ thống => | K1: SHOP | L1: GSM | M1: area_name | N1: region | P1: CODE | Q1: GSM | R1: RSM
A2: =ROW()-1 -> 1 | B2: A101 | C2: 45780 | D2: KFM_BDU_DAN - 27 Tân Lập | E2: =VLOOKUP(D2,$K$1:$M$237,3,0) -> HCM 027 | F2: =VLOOKUP(D2,$K$2:$L$176,2,0) -> Lê Ngọc Phát | K2: KFM_BDU_DAN - 01-06 TMDV Him Lam Phú Đông | L2: =VLOOKUP(M2,$P$2:$Q$39,2,0) -> Lê Ngọc Phát | M2: HCM 027 | N2: Regional Sales 3 | P2: HCM 001 | Q2: Nguyễn Minh Thắng | R2: Regional Sales 1
A3: =ROW()-1 -> 2 | B3: CHR | C3: 30/11/2024 | D3: KFM_BDU_DAN - S01.11 Block A1 Charm Sapphire | E3: =VLOOKUP(D3,$K$1:$M$237,3,0) -> HCM 017 | F3: =VLOOKUP(D3,$K$2:$L$176,2,0) -> Nguyễn Bữu Trùng Dương | K3: KFM_BDU_DAN - 27 Tân Lập | L3: =VLOOKUP(M3,$P$2:$Q$39,2,0) -> Lê Ngọc Phát | M3: HCM 027 | N3: Regional Sales 3 | P3: HCM 002 | Q3: Huỳnh Thị Tuyết Nhi | R3: Regional Sales 1
A4: =ROW()-1 -> 3 | B4: BCG | C4: 45241 | D4: KFM_BDU_DAN - SH01 BCons Garden | E4: =VLOOKUP(D4,$K$1:$M$237,3,0) -> HCM 017 | F4: =VLOOKUP(D4,$K$2:$L$176,2,0) -> Nguyễn Bữu Trùng Dương | K4: KFM_BDU_DAN - B2.01.05 Tháp B Opal Boulevard | L4: =VLOOKUP(M4,$P$2:$Q$39,2,0) -> Lê Ngọc Phát | M4: HCM 027 | N4: Regional Sales 3 | P4: HCM 003 | Q4: Nguyễn Thuỷ Tiên | R4: Regional Sales 1
A5: =ROW()-1 -> 4 | B5: OPS | C5: 29/03/2025 | D5: KFM_BDU_TAN - B.01.04 Tháp B Opal Skyline | E5: =VLOOKUP(D5,$K$1:$M$237,3,0) -> HCM 017 | F5: =VLOOKUP(D5,$K$2:$L$176,2,0) -> Nguyễn Bữu Trùng Dương | K5: KFM_BDU_DAN - S01.11 Block A1 Charm Sapphire | L5: =VLOOKUP(M5,$P$2:$Q$39,2,0) -> Nguyễn Bữu Trùng Dương | M5: HCM 017 | N5: Regional Sales 3 | P5: HCM 004 | Q5: Trần Kim Phụng | R5: Regional Sales 1
A6: =ROW()-1 -> 5 | B6: EMR | C6: 26/10/2024 | D6: KFM_BDU_TAN - Block A Emerald Golf View | E6: =VLOOKUP(D6,$K$1:$M$237,3,0) -> HCM 017 | F6: =VLOOKUP(D6,$K$2:$L$176,2,0) -> Nguyễn Bữu Trùng Dương | K6: KFM_BDU_DAN - SH01 BCons Garden | L6: =VLOOKUP(M6,$P$2:$Q$39,2,0) -> Nguyễn Bữu Trùng Dương | M6: HCM 017 | N6: Regional Sales 3 | P6: HCM 010 | Q6: Cao Chánh Tuấn | R6: Regional Sales 1
A7: =ROW()-1 -> 6 | B7: A117 | C7: 18/10/2025 | D7: KFM_BDU_TAN - SH04 The Rivana | E7: =VLOOKUP(D7,$K$1:$M$237,3,0) -> HCM 017 | F7: =VLOOKUP(D7,$K$2:$L$176,2,0) -> Nguyễn Bữu Trùng Dương | K7: KFM_BDU_TAN - B.01.04 Tháp B Opal Skyline | L7: =VLOOKUP(M7,$P$2:$Q$39,2,0) -> Nguyễn Bữu Trùng Dương | M7: HCM 017 | N7: Regional Sales 3 | P7: HCM 011 | Q7: Nguyễn Thị Tuyết Trinh | R7: Regional Sales 1
A8: =ROW()-1 -> 7 | B8: PHG | C8: 29/10/2021 | D8: KFM_HCM_BCH - 10 Phạm Hùng | E8: =VLOOKUP(D8,$K$1:$M$237,3,0) -> HCM 010 | F8: =VLOOKUP(D8,$K$2:$L$176,2,0) -> Cao Chánh Tuấn | K8: KFM_BDU_TAN - Block A Emerald Golf View | L8: =VLOOKUP(M8,$P$2:$Q$39,2,0) -> Nguyễn Bữu Trùng Dương | M8: HCM 017 | N8: Regional Sales 3 | P8: HCM 012 | Q8: Nguyễn Thị Ngọc Thảo | R8: Regional Sales 1
A9: =ROW()-1 -> 8 | B9: Q50 | C9: 45114 | D9: KFM_HCM_BCH - 511 Quốc Lộ 50 | E9: =VLOOKUP(D9,$K$1:$M$237,3,0) -> HCM 022 | F9: =VLOOKUP(D9,$K$2:$L$176,2,0) -> Hồng Trọng Nghĩa | K9: KFM_BDU_TAN - SH04 The Rivana | L9: =VLOOKUP(M9,$P$2:$Q$39,2,0) -> Nguyễn Bữu Trùng Dương | M9: HCM 017 | N9: Regional Sales 3 | P9: HCM 013 | Q9: Trần Huỳnh Thơ | R9: Regional Sales 1
A10: =ROW()-1 -> 9 | B10: A140 | C10: 27/12/2025 | D10: KFM_HCM_BCH - 68 Đường Số 1 Khu dân cư 6B Intresco | E10: =VLOOKUP(D10,$K$1:$M$237,3,0) -> HCM 010 | F10: =VLOOKUP(D10,$K$2:$L$176,2,0) -> Cao Chánh Tuấn | K10: KFM_HCM_BCH - 10 Phạm Hùng | L10: =VLOOKUP(M10,$P$2:$Q$39,2,0) -> Cao Chánh Tuấn | M10: HCM 010 | N10: Regional Sales 1 | P10: HCM 014 | Q10: Trần Văn Hiếu | R10: Regional Sales 1
A11: =ROW()-1 -> 10 | B11: MZ2 | C11: 13/07/2024 | D11: KFM_HCM_BCH - A7-8 Valora Mizuki | E11: =VLOOKUP(D11,$K$1:$M$237,3,0) -> HCM 022 | F11: =VLOOKUP(D11,$K$2:$L$176,2,0) -> Hồng Trọng Nghĩa | K11: KFM_HCM_BCH - 511 Quốc Lộ 50 | L11: =VLOOKUP(M11,$P$2:$Q$39,2,0) -> Hồng Trọng Nghĩa | M11: HCM 022 | N11: Regional Sales 1 | P11: HCM 015 | Q11: Trần Hữu Vinh | R11: Regional Sales 1
A12: =ROW()-1 -> 11 | B12: A133 | C12: 46082 | D12: KFM_HCM_BCH - Block G Conic Skyway | E12: =VLOOKUP(D12,$K$1:$M$237,3,0) -> HCM 022 | F12: =VLOOKUP(D12,$K$2:$L$176,2,0) -> Hồng Trọng Nghĩa | K12: KFM_HCM_BCH - 68 Đường Số 1 Khu dân cư 6B Intresco | L12: =VLOOKUP(M12,$P$2:$Q$39,2,0) -> Cao Chánh Tuấn | M12: HCM 010 | N12: Regional Sales 1 | P12: HCM 022 | Q12: Hồng Trọng Nghĩa | R12: Regional Sales 1
A13: =ROW()-1 -> 12 | B13: WGA | C13: 31/08/2024 | D13: KFM_HCM_BCH - D-2.01A Westgate An Gia | E13: =VLOOKUP(D13,$K$1:$M$237,3,0) -> HCM 011 | F13: =VLOOKUP(D13,$K$2:$L$176,2,0) -> Nguyễn Thị Tuyết Trinh | K13: KFM_HCM_BCH - A7-8 Valora Mizuki | L13: =VLOOKUP(M13,$P$2:$Q$39,2,0) -> Hồng Trọng Nghĩa | M13: HCM 022 | N13: Regional Sales 1 | P13: HCM 023 | Q13: Hứa Thái Hiển | R13: Regional Sales 1
A14: =ROW()-1 -> 13 | B14: MZK | C14: 14/10/2023 | D14: KFM_HCM_BCH - TMDV2 Mizuki Park | E14: =VLOOKUP(D14,$K$1:$M$237,3,0) -> HCM 022 | F14: =VLOOKUP(D14,$K$2:$L$176,2,0) -> Hồng Trọng Nghĩa | K14: KFM_HCM_BCH - Block G Conic Skyway | L14: =VLOOKUP(M14,$P$2:$Q$39,2,0) -> Hồng Trọng Nghĩa | M14: HCM 022 | N14: Regional Sales 1 | P14: HCM 024 | Q14: Phạm Duy | R14: Regional Sales 1
A15: =ROW()-1 -> 14 | B15: A139 | C15: 25/12/2025 | D15: KFM_HCM_BTA - 197 Đường số 1 An Lạc | E15: =VLOOKUP(D15,$K$1:$M$237,3,0) -> HCM 031 | F15: =VLOOKUP(D15,$K$2:$L$176,2,0) -> Nguyễn Thị Ngọc Giàu | K15: KFM_HCM_BCH - D-2.01A Westgate An Gia | L15: =VLOOKUP(M15,$P$2:$Q$39,2,0) -> Nguyễn Thị Tuyết Trinh | M15: HCM 011 | N15: Regional Sales 1 | P15: HCM 028 | Q15: Lâm Văn Tú | R15: Regional Sales 1
A16: =ROW()-1 -> 15 | B16: NTU | C16: 14/10/2022 | D16: KFM_HCM_BTA - 46 Nguyễn Thị Tú | E16: =VLOOKUP(D16,$K$1:$M$237,3,0) -> HCM 012 | F16: =VLOOKUP(D16,$K$2:$L$176,2,0) -> Nguyễn Thị Ngọc Thảo | K16: KFM_HCM_BCH - TMDV2 Mizuki Park | L16: =VLOOKUP(M16,$P$2:$Q$39,2,0) -> Hồng Trọng Nghĩa | M16: HCM 022 | N16: Regional Sales 1 | P16: HCM 029 | Q16: Võ Văn Phi Hùng | R16: Regional Sales 1
A17: =ROW()-1 -> 16 | B17: BTH | C17: 27/09/2024 | D17: KFM_HCM_BTA - 66/70 Bình Thành | E17: =VLOOKUP(D17,$K$1:$M$237,3,0) -> HCM 012 | F17: =VLOOKUP(D17,$K$2:$L$176,2,0) -> Nguyễn Thị Ngọc Thảo | K17: KFM_HCM_BTA - 197 Đường số 1 An Lạc | L17: =VLOOKUP(M17,$P$2:$Q$39,2,0) -> Nguyễn Thị Ngọc Giàu | M17: HCM 031 | N17: Regional Sales 1 | P17: HCM 030 | Q17: Trương Công Nhật Tùng | R17: Regional Sales 1
A18: =ROW()-1 -> 17 | B18: DS7 | C18: 45233 | D18: KFM_HCM_BTA - 99 Đường Số 7 | E18: =VLOOKUP(D18,$K$1:$M$237,3,0) -> HCM 031 | F18: =VLOOKUP(D18,$K$2:$L$176,2,0) -> Nguyễn Thị Ngọc Giàu | K18: KFM_HCM_BTA - 4535 Nguyễn Cửu Phú | L18: =VLOOKUP(M18,$P$2:$Q$39,2,0) -> Nguyễn Thị Ngọc Giàu | M18: HCM 031 | N18: Regional Sales 1 | P18: HCM 031 | Q18: Nguyễn Thị Ngọc Giàu | R18: Regional Sales 1
A19: =ROW()-1 -> 18 | B19: EH3 | C19: 28/12/2024 | D19: KFM_HCM_BTA - A10-0.02 Ehome 3 | E19: =VLOOKUP(D19,$K$1:$M$237,3,0) -> HCM 011 | F19: =VLOOKUP(D19,$K$2:$L$176,2,0) -> Nguyễn Thị Tuyết Trinh | K19: KFM_HCM_BTA - 46 Nguyễn Thị Tú | L19: =VLOOKUP(M19,$P$2:$Q$39,2,0) -> Nguyễn Thị Ngọc Thảo | M19: HCM 012 | N19: Regional Sales 1 | P19: HCM 032 | Q19: Võ Thị Thùy Dương | R19: Regional Sales 1
A20: =ROW()-1 -> 19 | B20: AKR | C20: 27/01/2024 | D20: KFM_HCM_BTA - AK4 Akari City | E20: =VLOOKUP(D20,$K$1:$M$237,3,0) -> HCM 011 | F20: =VLOOKUP(D20,$K$2:$L$176,2,0) -> Nguyễn Thị Tuyết Trinh | K20: KFM_HCM_BTA - 66/70 Bình Thành | L20: =VLOOKUP(M20,$P$2:$Q$39,2,0) -> Nguyễn Thị Ngọc Thảo | M20: HCM 012 | N20: Regional Sales 1 | P20: HCM 005 | Q20: Nguyễn Thị Ngọc Bích | R20: Regional Sales 3
A21: =ROW()-1 -> 20 | B21: PKD | C21: 19/04/2025 | D21: KFM_HCM_BTA - TMDV19 Privia Khang Điền | E21: =VLOOKUP(D21,$K$1:$M$237,3,0) -> HCM 029 | F21: =VLOOKUP(D21,$K$2:$L$176,2,0) -> Võ Văn Phi Hùng | K21: KFM_HCM_BTA - 99 Đường Số 7 | L21: =VLOOKUP(M21,$P$2:$Q$39,2,0) -> Nguyễn Thị Ngọc Giàu | M21: HCM 031 | N21: Regional Sales 1 | P21: HCM 006 | Q21: Nguyễn Đình Vũ | R21: Regional Sales 3
A22: =ROW()-1 -> 21 | B22: BQI | C22: 21/07/2023 | D22: KFM_HCM_BTH - 107 Bình Quới | E22: =VLOOKUP(D22,$K$1:$M$237,3,0) -> HCM 025 | F22: =VLOOKUP(D22,$K$2:$L$176,2,0) -> Đoàn Ngọc Thịnh | K22: KFM_HCM_BTA - A10-0.02 Ehome 3 | L22: =VLOOKUP(M22,$P$2:$Q$39,2,0) -> Nguyễn Thị Tuyết Trinh | M22: HCM 011 | N22: Regional Sales 1 | P22: HCM 007 | Q22: Nguyễn Văn Lâm | R22: Regional Sales 3
A23: =ROW()-1 -> 22 | B23: NTO | C23: 30/05/2024 | D23: KFM_HCM_BTH - 108 Ngô Tất Tố | E23: =VLOOKUP(D23,$K$1:$M$237,3,0) -> HCM 018 | F23: =VLOOKUP(D23,$K$2:$L$176,2,0) -> Võ Minh Đạt | K23: KFM_HCM_BTA - AK4 Akari City | L23: =VLOOKUP(M23,$P$2:$Q$39,2,0) -> Nguyễn Thị Tuyết Trinh | M23: HCM 011 | N23: Regional Sales 1 | P23: HCM 008 | Q23: Lê Ngọc Thảo | R23: Regional Sales 3
A24: =ROW()-1 -> 23 | B24: A113 | C24: 45933 | D24: KFM_HCM_BTH - 216 Phan Văn Hân | E24: =VLOOKUP(D24,$K$1:$M$237,3,0) -> HCM 016 | F24: =VLOOKUP(D24,$K$2:$L$176,2,0) -> Lê Nguyễn Ngọc Phượng | K24: KFM_HCM_BTA - TMDV19 Privia Khang Điền | L24: =VLOOKUP(M24,$P$2:$Q$39,2,0) -> Võ Văn Phi Hùng | M24: HCM 029 | N24: Regional Sales 1 | P24: HCM 009 | Q24: Lê Huỳnh Thiện | R24: Regional Sales 3
A25: =ROW()-1 -> 24 | B25: NVD | C25: 45505 | D25: KFM_HCM_BTH - 42 Nguyễn Văn Đậu | E25: =VLOOKUP(D25,$K$1:$M$237,3,0) -> HCM 025 | F25: =VLOOKUP(D25,$K$2:$L$176,2,0) -> Đoàn Ngọc Thịnh | K25: KFM_HCM_BTH - 107 Bình Quới | L25: =VLOOKUP(M25,$P$2:$Q$39,2,0) -> Đoàn Ngọc Thịnh | M25: HCM 025 | N25: Regional Sales 3 | P25: HCM 016 | Q25: Lê Nguyễn Ngọc Phượng | R25: Regional Sales 3
A26: =ROW()-1 -> 25 | B26: A115 | C26: 45940 | D26: KFM_HCM_BTH - 484B Lê Quang Định | E26: =VLOOKUP(D26,$K$1:$M$237,3,0) -> HCM 025 | F26: =VLOOKUP(D26,$K$2:$L$176,2,0) -> Đoàn Ngọc Thịnh | K26: KFM_HCM_BTH - 108 Ngô Tất Tố | L26: =VLOOKUP(M26,$P$2:$Q$39,2,0) -> Võ Minh Đạt | M26: HCM 018 | N26: Regional Sales 3 | P26: HCM 017 | Q26: Nguyễn Bữu Trùng Dương | R26: Regional Sales 3
A27: =ROW()-1 -> 26 | B27: VHT | C27: 44654 | D27: KFM_HCM_BTH - 54 Vũ Huy Tấn | E27: =VLOOKUP(D27,$K$1:$M$237,3,0) -> HCM 016 | F27: =VLOOKUP(D27,$K$2:$L$176,2,0) -> Lê Nguyễn Ngọc Phượng | K27: KFM_HCM_BTH - 127 Tân Cảng | L27: =VLOOKUP(M27,$P$2:$Q$39,2,0) -> Võ Minh Đạt | M27: HCM 018 | N27: Regional Sales 3 | P27: HCM 018 | Q27: Võ Minh Đạt | R27: Regional Sales 3
A28: =ROW()-1 -> 27 | B28: VTG | C28: 26/08/2022 | D28: KFM_HCM_BTH - 86B Vũ Tùng | E28: =VLOOKUP(D28,$K$1:$M$237,3,0) -> HCM 016 | F28: =VLOOKUP(D28,$K$2:$L$176,2,0) -> Lê Nguyễn Ngọc Phượng | K28: KFM_HCM_BTH - 216 Phan Văn Hân | L28: =VLOOKUP(M28,$P$2:$Q$39,2,0) -> Lê Nguyễn Ngọc Phượng | M28: HCM 016 | N28: Regional Sales 3 | P28: HCM 019 | Q28: Trần Thanh Hiền | R28: Regional Sales 3
A29: =ROW()-1 -> 28 | B29: NHG | C29: 23/07/2022 | D29: KFM_HCM_GVA - 15 Nguyên Hồng | E29: =VLOOKUP(D29,$K$1:$M$237,3,0) -> HCM 025 | F29: =VLOOKUP(D29,$K$2:$L$176,2,0) -> Đoàn Ngọc Thịnh | K29: KFM_HCM_BTH - 42 Nguyễn Văn Đậu | L29: =VLOOKUP(M29,$P$2:$Q$39,2,0) -> Đoàn Ngọc Thịnh | M29: HCM 025 | N29: Regional Sales 3 | P29: HCM 020 | Q29: Phạm Hữu Chương | R29: Regional Sales 3
A30: =ROW()-1 -> 29 | B30: TNT | C30: 19/05/2023 | D30: KFM_HCM_GVA - 195 Thống Nhất | E30: =VLOOKUP(D30,$K$1:$M$237,3,0) -> HCM 008 | F30: =VLOOKUP(D30,$K$2:$L$176,2,0) -> Lê Ngọc Thảo | K30: KFM_HCM_BTH - 484B Lê Quang Định | L30: =VLOOKUP(M30,$P$2:$Q$39,2,0) -> Đoàn Ngọc Thịnh | M30: HCM 025 | N30: Regional Sales 3 | P30: HCM 021 | Q30: Hồ Xuân Thịnh | R30: Regional Sales 3
A31: =ROW()-1 -> 30 | B31: A151 | C31: 23/01/2026 | D31: KFM_HCM_GVA - 20 Lê Đức Thọ | E31: =VLOOKUP(D31,$K$1:$M$237,3,0) -> HCM 008 | F31: =VLOOKUP(D31,$K$2:$L$176,2,0) -> Lê Ngọc Thảo | K31: KFM_HCM_BTH - 54 Vũ Huy Tấn | L31: =VLOOKUP(M31,$P$2:$Q$39,2,0) -> Lê Nguyễn Ngọc Phượng | M31: HCM 016 | N31: Regional Sales 3 | P31: HCM 025 | Q31: Đoàn Ngọc Thịnh | R31: Regional Sales 3
A32: =ROW()-1 -> 31 | B32: NVK | C32: 45568 | D32: KFM_HCM_GVA - 299 Nguyễn Văn Khối | E32: =VLOOKUP(D32,$K$1:$M$237,3,0) -> HCM 036 | F32: =VLOOKUP(D32,$K$2:$L$176,2,0) -> Đặng Đăng Khoa | K32: KFM_HCM_BTH - 61 Bùi Đình Túy | L32: =VLOOKUP(M32,$P$2:$Q$39,2,0) -> Lê Nguyễn Ngọc Phượng | M32: HCM 016 | N32: Regional Sales 3 | P32: HCM 026 | Q32: Trần Tiến Thạnh | R32: Regional Sales 3
A33: =ROW()-1 -> 32 | B33: LVT | C33: 21/07/2022 | D33: KFM_HCM_GVA - 308 Lê Văn Thọ | E33: =VLOOKUP(D33,$K$1:$M$237,3,0) -> HCM 008 | F33: =VLOOKUP(D33,$K$2:$L$176,2,0) -> Lê Ngọc Thảo | K33: KFM_HCM_BTH - 86B Vũ Tùng | L33: =VLOOKUP(M33,$P$2:$Q$39,2,0) -> Lê Nguyễn Ngọc Phượng | M33: HCM 016 | N33: Regional Sales 3 | P33: HCM 027 | Q33: Lê Ngọc Phát | R33: Regional Sales 3
A34: =ROW()-1 -> 33 | B34: NKM | C34: 44688 | D34: KFM_HCM_GVA - 371 Nguyễn Kiệm | E34: =VLOOKUP(D34,$K$1:$M$237,3,0) -> HCM 033 | F34: =VLOOKUP(D34,$K$2:$L$176,2,0) -> Huỳnh Ngọc Phương | K34: KFM_HCM_GVA - 15 Nguyên Hồng | L34: =VLOOKUP(M34,$P$2:$Q$39,2,0) -> Đoàn Ngọc Thịnh | M34: HCM 025 | N34: Regional Sales 3 | P34: HCM 033 | Q34: Huỳnh Ngọc Phương | R34: Regional Sales 3
A35: =ROW()-1 -> 34 | B35: DQH | C35: 23/02/2023 | D35: KFM_HCM_GVA - 372 Dương Quảng Hàm | E35: =VLOOKUP(D35,$K$1:$M$237,3,0) -> HCM 033 | F35: =VLOOKUP(D35,$K$2:$L$176,2,0) -> Huỳnh Ngọc Phương | K35: KFM_HCM_GVA - 195 Thống Nhất | L35: =VLOOKUP(M35,$P$2:$Q$39,2,0) -> Lê Ngọc Thảo | M35: HCM 008 | N35: Regional Sales 3 | P35: HCM 034 | Q35: Lê Thị Bích Liểu | R35: Regional Sales 3
A36: =ROW()-1 -> 35 | B36: PHI | C36: 23/09/2022 | D36: KFM_HCM_GVA - 410 Phan Huy Ích | E36: =VLOOKUP(D36,$K$1:$M$237,3,0) -> HCM 009 | F36: =VLOOKUP(D36,$K$2:$L$176,2,0) -> Lê Huỳnh Thiện | K36: KFM_HCM_GVA - 20 Lê Đức Thọ | L36: =VLOOKUP(M36,$P$2:$Q$39,2,0) -> Lê Ngọc Thảo | M36: HCM 008 | N36: Regional Sales 3 | P36: HCM 035 | Q36: Đào Hồng Hiện | R36: Regional Sales 3
A37: =ROW()-1 -> 36 | B37: PVB | C37: 45786 | D37: KFM_HCM_GVA - 446 Phạm Văn Bạch | E37: =VLOOKUP(D37,$K$1:$M$237,3,0) -> HCM 009 | F37: =VLOOKUP(D37,$K$2:$L$176,2,0) -> Lê Huỳnh Thiện | K37: KFM_HCM_GVA - 299 Nguyễn Văn Khối | L37: =VLOOKUP(M37,$P$2:$Q$39,2,0) -> Đặng Đăng Khoa | M37: HCM 036 | N37: Regional Sales 3 | P37: HCM 036 | Q37: Đặng Đăng Khoa | R37: Regional Sales 3
A38: =ROW()-1 -> 37 | B38: A128 | C38: 45820 | D38: KFM_HCM_GVA - TM0.03 CH3 Cityland Park Hill | E38: =VLOOKUP(D38,$K$1:$M$237,3,0) -> HCM 008 | F38: =VLOOKUP(D38,$K$2:$L$176,2,0) -> Lê Ngọc Thảo | K38: KFM_HCM_GVA - 308 Lê Văn Thọ | L38: =VLOOKUP(M38,$P$2:$Q$39,2,0) -> Lê Ngọc Thảo | M38: HCM 008 | N38: Regional Sales 3
A39: =ROW()-1 -> 38 | B39: LVL | C39: 18/11/2022 | D39: KFM_HCM_NBE - 166E Lê Văn Lương | E39: =VLOOKUP(D39,$K$1:$M$237,3,0) -> HCM 004 | F39: =VLOOKUP(D39,$K$2:$L$176,2,0) -> Trần Kim Phụng | K39: KFM_HCM_GVA - 371 Nguyễn Kiệm | L39: =VLOOKUP(M39,$P$2:$Q$39,2,0) -> Huỳnh Ngọc Phương | M39: HCM 033 | N39: Regional Sales 3
A40: =ROW()-1 -> 39 | B40: A103 | C40: 45842 | D40: KFM_HCM_NBE - 222 Lê Văn Lương | E40: =VLOOKUP(D40,$K$1:$M$237,3,0) -> HCM 004 | F40: =VLOOKUP(D40,$K$2:$L$176,2,0) -> Trần Kim Phụng | K40: KFM_HCM_GVA - 372 Dương Quảng Hàm | L40: =VLOOKUP(M40,$P$2:$Q$39,2,0) -> Huỳnh Ngọc Phương | M40: HCM 033 | N40: Regional Sales 3
...

Sheet Timeline phối hợp 
B1: Timeline phối hợp giữa các bộ phận
A3: Bộ phận | B3: Nội dung | C3: Thời gian
A4: OPS | B4: Gửi thông báo lịch kiểm kê cuối năm | C4: D-30
A5: OPS | B5: Cài đặt lịch kiểm kê trên hệ thống theo siêu thị | C5: D-7
A6: IC/OPS | B6: Nhân sự kiểm soát quy trình kiểm kê nếu có | C6: D
A7: OPS | B7: Phân tích kết quả kiểm kê hàng tháng | C7: Ngày 7 hàng tháng
A8: SOC | B8: Tổ chức kiểm tra tồn kho chính xác sau kiểm kê | C8: theo kế hoạch
A9: SCM | B9: Thông báo NCC xử lý dứt điểm hàng chờ đổi trả | C9: D-15
A10: SCM/Store | B10: Ngưng lệnh chuyển hàng giữa các Siêu thị | C10: D-1
A11: Training | B11: Đào tạo quy trình kiểm kê, hướng dẫn app kiểm kê | C11: D-15
A12: IT | B12: Gửi lịch trực hỗ trợ về hệ thống kiểm kê | C12: D-15
A13: IT | B13: Nhân sự trực đảm bảo hệ thống kiểm kê ổn định | C13: D
A14: IT | B14: Chặn chuyển hàng từ ST đến ST | C14: D
... A25: C&B | B25: Tính thưởng/trách nhiệm kiểm kê theo chính sách nếu có | C25: ngày 2 hàng tháng

Sheet Sheet6
C1: LỊCH KIỂM KÊ TỔNG 2025 | O1: STT | P1: opening_date | Q1: store | R1: location_type | S1: ASM
C2: Thời gian: 01/04/2025 - 29/12/2025 | O2: =ROW()-1 -> 1 | P2: 43112 | Q2: KFM_HCM_Q07 - 31 Tân Mỹ - MART | R2: RIVER | S2: HCM 001-Nguyễn Minh Thắng | T2: =VLOOKUP(Q2,'Lịch kiểm kê 2025'!E:E,1,0) -> KFM_HCM_Q07 - 31 Tân Mỹ - MART
C3: Ngô Quang Cẩm Tú | O3: =ROW()-1 -> 2 | P3: 20/12/19 | Q3: KFM_HCM_Q10 - BB17 Trường Sơn - MART | R3: STREAM | S3: HCM 013-Trần Huỳnh Thơ | T3: =VLOOKUP(Q3,'Lịch kiểm kê 2025'!E:E,1,0) -> KFM_HCM_Q10 - BB17 Trường Sơn - MART
C4: Hoàng Ngọc Long | O4: =ROW()-1 -> 3 | P4: 44114 | Q4: KFM_HCM_TBI - 22 Hoàng Hoa Thám - MART | R4: STREAM | S4: HCM 015-Trần Hữu Vinh | T4: =VLOOKUP(Q4,'Lịch kiểm kê 2025'!E:E,1,0) -> KFM_HCM_TBI - 22 Hoàng Hoa Thám - MART
C5: Tô Thanh Vinh | G5: ID Mart | H5: Name Mart | I5: KHU VỰC | K5: KHU VỰC | L5: GSM | M5: HỌ VÀ TÊN | O5: =ROW()-1 -> 4 | P5: 23/1/21 | Q5: KFM_HCM_Q07 - 571 Huỳnh Tấn Phát - MART | R5: RIVER | S5: HCM 002-Hứa Thái Hiển | T5: =VLOOKUP(Q5,'Lịch kiểm kê 2025'!E:E,1,0) -> KFM_HCM_Q07 - 571 Huỳnh Tấn Phát - MART
C6: Nguyễn Thanh Tùng | G6: TMY | H6: KFM_HCM_Q07 - 31 Tân Mỹ - MART | I6: HCM 1 | K6: HCM 1 | L6: GSM 1 | M6: Nguyễn Minh Thắng | O6: =ROW()-1 -> 5 | P6: 29/10/21 | Q6: KFM_HCM_BCH - 10 Phạm Hùng - MART | R6: RIVER | T6: =VLOOKUP(Q6,'Lịch kiểm kê 2025'!E:E,1,0) -> KFM_HCM_BCH - 10 Phạm Hùng - MART
C7: Nguyễn Xuân Hoánh | G7: BVB | H7: KFM_HCM_Q07 - 43 Bùi Văn Ba - MINI | I7: HCM 1 | K7: HCM 2 | L7: GSM 2 | M7: Hứa Thái Hiển | O7: =ROW()-1 -> 6 | P7: 22/1/22 | Q7: KFM_HCM_Q07 - 436 Nguyễn Thị Thập - MART | R7: RIVER | S7: HCM 003-Nguyễn Thuỷ Tiên | T7: =VLOOKUP(Q7,'Lịch kiểm kê 2025'!E:E,1,0) -> KFM_HCM_Q07 - 436 Nguyễn Thị Thập - MART
G8: ECG | H8: KFM_HCM_Q07 - SH16 Eco Green - MINI | I8: HCM 1 | K8: HCM 3 | L8: GSM 3 | M8: Nguyễn Thuỷ Tiên | O8: =ROW()-1 -> 7 | P8: 44624 | Q8: KFM_HCM_BTH - 54 Vũ Huy Tấn - MINI | R8: STREAM | S8: HCM 016-Cao Chánh Tuấn | T8: =VLOOKUP(Q8,'Lịch kiểm kê 2025'!E:E,1,0) -> KFM_HCM_BTH - 54 Vũ Huy Tấn - MINI
A9: ID Mart | B9: KV | C9: Tên Siêu thị | G9: SCV | H9: KFM_HCM_Q07 - B0.02 Scenic Valley 2 - MINI | I9: HCM 1 | K9: HCM 4 | L9: GSM 4 | M9: Trần Kim Phụng | O9: =ROW()-1 -> 8 | P9: 30/4/22 | Q9: KFM_HCM_GVA - 371 Nguyễn Kiệm - MINI | R9: LAKE | S9: HCM 008-Huỳnh Ngọc Phương | T9: =VLOOKUP(Q9,'Lịch kiểm kê 2025'!E:E,1,0) -> KFM_HCM_GVA - 371 Nguyễn Kiệm - MINI
A10: =XLOOKUP(C10,H:H,G:G) -> ERT | B10: HCM 1 | C10: KFM_HCM_Q07 - 0105 B4 Era Town - MART | G10: HV2 | H10: KFM_HCM_Q07 - R13 Hưng Vượng 2 - MINI | I10: HCM 1 | K10: HCM 5 | L10: GSM 5 | M10: Trương Công Nhật Tùng | O10: =ROW()-1 -> 9 | P10: 13/5/22 | Q10: KFM_HCM_Q07 - 43 Bùi Văn Ba - MINI | R10: STREAM | S10: HCM 001-Nguyễn Minh Thắng | T10: =VLOOKUP(Q10,'Lịch kiểm kê 2025'!E:E,1,0) -> KFM_HCM_Q07 - 43 Bùi Văn Ba - MINI
A11: =XLOOKUP(C11,H:H,G:G) -> DS7 | B11: HCM 4 | C11: KFM_HCM_BTA - 99 Đường Số 7 - MINI | G11: RVS | H11: KFM_HCM_Q07 - C0.01 Riverside Phú Mỹ Hưng - MART | I11: HCM 1 | K11: HCM 6 | L11: GSM 6 | M11: Nguyễn Đình Vũ | O11: =ROW()-1 -> 10 | P11: 21/7/22 | Q11: KFM_HCM_GVA - 308 Lê Văn Thọ - MINI | R11: RIVER | S11: HCM 008-Huỳnh Ngọc Phương | T11: =VLOOKUP(Q11,'Lịch kiểm kê 2025'!E:E,1,0) -> KFM_HCM_GVA - 308 Lê Văn Thọ - MINI
A12: =XLOOKUP(C12,H:H,G:G) -> PHG | B12: HCM 4 | C12: KFM_HCM_BCH - 10 Phạm Hùng - MART | G12: HTP | H12: KFM_HCM_Q07 - 571 Huỳnh Tấn Phát - MART | I12: HCM 2 | K12: HCM 7 | L12: GSM 7 | M12: Nguyễn Văn Lâm | O12: =ROW()-1 -> 11 | P12: 23/7/22 | Q12: KFM_HCM_GVA - 15 Nguyên Hồng - MINI | R12: RIVER | S12: HCM 016-Cao Chánh Tuấn | T12: =VLOOKUP(Q12,'Lịch kiểm kê 2025'!E:E,1,0) -> KFM_HCM_GVA - 15 Nguyên Hồng - MINI
A13: =XLOOKUP(C13,H:H,G:G) -> MZK | B13: HCM 4 | C13: KFM_HCM_BCH - TMDV2 Mizuki Park - MINI | G13: LTC | H13: KFM_HCM_Q07 - 97 Lê Thị Chợ - MINI | I13: HCM 2 | K13: HCM 8 | L13: GSM 8 | M13: Huỳnh Ngọc Phương | O13: =ROW()-1 -> 12 | P13: 29/7/22 | Q13: KFM_HCM_Q04 - 98 Khánh Hội - MINI | R13: LAKE | S13: HCM 003-Nguyễn Thuỷ Tiên | T13: =VLOOKUP(Q13,'Lịch kiểm kê 2025'!E:E,1,0) -> KFM_HCM_Q04 - 98 Khánh Hội - MINI
A14: =XLOOKUP(C14,H:H,G:G) -> LPM | B14: HCM 1 | C14: KFM_HCM_Q07 - 39 Lý Phục Man - MINI | G14: PTN | H14: KFM_HCM_Q07 - E72 Phú Thuận - MINI | I14: HCM 2 | K14: HCM 9 | L14: GSM 9 | M14: Lâm Văn Tú | O14: =ROW()-1 -> 13 | P14: 44689 | Q14: KFM_HCM_TPH - 85 Cây Keo - MINI | R14: STREAM | S14: HCM 014-Trần Văn Hiếu | T14: =VLOOKUP(Q14,'Lịch kiểm kê 2025'!E:E,1,0) -> KFM_HCM_TPH - 85 Cây Keo - MINI
A15: =XLOOKUP(C15,H:H,G:G) -> LTC | B15: HCM 1 | C15: KFM_HCM_Q07 - 97 Lê Thị Chợ - MINI | G15: LPM | H15: KFM_HCM_Q07 - 39 Lý Phục Man - MINI | I15: HCM 2 | K15: HCM 10 | L15: GSM 10 | M15: Phan Ngọc Trí | O15: =ROW()-1 -> 14 | P15: 44720 | Q15: KFM_HCM_Q09 - 367 Nguyễn Văn Tăng - MINI | R15: RIVER | S15: HCM 005-Trương Công Nhật Tùng | T15: =VLOOKUP(Q15,'Lịch kiểm kê 2025'!E:E,1,0) -> KFM_HCM_Q09 - 367 Nguyễn Văn Tăng - MINI
A16: =XLOOKUP(C16,H:H,G:G) -> DS10 | B16: HCM 1 | C16: KFM_HCM_Q7 - 01 Đường Số 10 Tân Kiểng - MINI | G16: Q7R | H16: KFM_HCM_Q07 - Lô CD L1-12 Q7 Riverside Đào Trí - MINI | I16: HCM 2 | K16: HCM 11 | L16: GSM 11 | M16: Nguyễn Thị Tuyết Trinh | O16: =ROW()-1 -> 15 | P16: 26/8/22 | Q16: KFM_HCM_BTH - 86B Vũ Tùng - MINI | R16: STREAM | S16: HCM 016-Cao Chánh Tuấn | T16: =VLOOKUP(Q16,'Lịch kiểm kê 2025'!E:E,1,0) -> KFM_HCM_BTH - 86B Vũ Tùng - MINI
A17: =XLOOKUP(C17,H:H,G:G) -> NDT | B17: HCM 5 | C17: KFM_HCM_TDU - 305 Nguyễn Duy Trinh - MART | G17: NTT | H17: KFM_HCM_Q07 - 436 Nguyễn Thị Thập - MART | I17: HCM 3 | K17: HCM 12 | L17: GSM 12 | M17: Nguyễn Thị Ngọc Thảo | O17: =ROW()-1 -> 16 | P17: 23/9/22 | Q17: KFM_HCM_GVA - 410 Phan Huy Ích - MART | R17: RIVER | S17: HCM 009-Lâm Văn Tú | T17: =VLOOKUP(Q17,'Lịch kiểm kê 2025'!E:E,1,0) -> KFM_HCM_GVA - 410 Phan Huy Ích - MART
A18: =XLOOKUP(C18,H:H,G:G) -> IAP | B18: HCM 5 | C18: KFM_HCM_TDU - Block B Imperia An Phú - MART | G18: LVN | H18: KFM_HCM_Q07 - 09 Lâm Văn Bền - MINI | I18: HCM 3 | K18: HCM 13 | L18: GSM 13 | M18: Trần Huỳnh Thơ | O18: =ROW()-1 -> 17 | P18: 14/10/22 | Q18: KFM_HCM_BTA - 46 Nguyễn Thị Tú - MINI | R18: RIVER | S18: HCM 012-Nguyễn Thị Ngọc Thảo | T18: =VLOOKUP(Q18,'Lịch kiểm kê 2025'!E:E,1,0) -> KFM_HCM_BTA - 46 Nguyễn Thị Tú - MINI
A19: =XLOOKUP(C19,H:H,G:G) -> HTN | B19: HCM 5 | C19: KFM_HCM_TDU - 17 Hồ Thị Nhung - MINI | G19: DS10 | H19: KFM_HCM_Q7 - 01 Đường Số 10 Tân Kiểng - MINI | I19: HCM 3 | K19: HCM 14 | L19: GSM 14 | M19: Trần Văn Hiếu | O19: =ROW()-1 -> 18 | P19: 25/10/22 | Q19: KFM_HCM_TPH - 48 CN1 - MINI | R19: STREAM | S19: HCM 012-Nguyễn Thị Ngọc Thảo | T19: =VLOOKUP(Q19,'Lịch kiểm kê 2025'!E:E,1,0) -> KFM_HCM_TPH - 48 CN1 - MINI
A20: =XLOOKUP(C20,H:H,G:G) -> NTD | B20: HCM 5 | C20: KFM_HCM_TDU - 160A Nguyễn Thị Định - MINI | G20: D67 | H20: KFM_HCM_Q07 - 10 Đường Số 67 Tân Kiểng - MINI | I20: HCM 3 | K20: HCM 15 | L20: GSM 15 | M20: Trần Hữu Vinh | O20: =ROW()-1 -> 19 | P20: 27/10/22 | Q20: KFM_HCM_Q07 - 233 Phạm Hữu Lầu - MINI | R20: STREAM | S20: HCM 004-Trần Kim Phụng | T20: =VLOOKUP(Q20,'Lịch kiểm kê 2025'!E:E,1,0) -> KFM_HCM_Q07 - 233 Phạm Hữu Lầu - MINI
A21: =XLOOKUP(C21,H:H,G:G) -> NTO | B21: HCM 5 | C21: KFM_HCM_BTH - 108 Ngô Tất Tố - MINI | G21: KHI | H21: KFM_HCM_Q04 - 98 Khánh Hội - MINI | I21: HCM 3 | K21: HCM 16 | L21: GSM 16 | M21: Cao Chánh Tuấn | O21: =ROW()-1 -> 20 | P21: 18/11/22 | Q21: KFM_HCM_NBE - 166E Lê Văn Lương - MART | R21: RIVER | S21: HCM 004-Trần Kim Phụng | T21: =VLOOKUP(Q21,'Lịch kiểm kê 2025'!E:E,1,0) -> KFM_HCM_NBE - 166E Lê Văn Lương - MART
A22: =XLOOKUP(C22,H:H,G:G) -> HNG | B22: HCM 3 | C22: KFM_HCM_Q12 - Block B1 Hưng Ngân Garden - MINI | G22: LVL | H22: KFM_HCM_NBE - 166E Lê Văn Lương - MART | I22: HCM 4 | K22: HCM 17 | L22: GSM 17 | M22: Nguyễn Bửu Trùng Dương | O22: =ROW()-1 -> 21 | P22: 45261 | Q22: KFM_HCM_Q07 - 09 Lâm Văn Bền - MINI | R22: STREAM | S22: HCM 003-Nguyễn Thuỷ Tiên | T22: =VLOOKUP(Q22,'Lịch kiểm kê 2025'!E:E,1,0) -> KFM_HCM_Q07 - 09 Lâm Văn Bền - MINI
A23: =XLOOKUP(C23,H:H,G:G) -> CLG | B23: HCM 3 | C23: KFM_HCM_TBI - 64A Cửu Long - MINI | G23: PHL | H23: KFM_HCM_Q07 - 233 Phạm Hữu Lầu - MINI | I23: HCM 4 | K23: HCM 18 | L23: GSM 18 | M23: Võ Minh Đạt | O23: =ROW()-1 -> 22 | P23: 23/2/23 | Q23: KFM_HCM_GVA - 372 Dương Quảng Hàm - MINI | R23: STREAM | S23: HCM 008-Huỳnh Ngọc Phương | T23: =VLOOKUP(Q23,'Lịch kiểm kê 2025'!E:E,1,0) -> KFM_HCM_GVA - 372 Dương Quảng Hàm - MINI
A24: =XLOOKUP(C24,H:H,G:G) -> ACU | B24: HCM 5 | C24: KFM_HCM_TDU - 0.01 Chung cư An Cư An Phú - MINI | G24: ERT | H24: KFM_HCM_Q07 - 0105 B4 Era Town - MART | I24: HCM 4 | K24: HCM 19 | L24: GSM 19 | M24: Trần Thanh Hiền | O24: =ROW()-1 -> 23 | P24: 24/2/23 | Q24: KFM_HCM_Q07 - 0105 B4 Era Town - MART | R24: LAKE | S24: HCM 004-Trần Kim Phụng | T24: =VLOOKUP(Q24,'Lịch kiểm kê 2025'!E:E,1,0) -> KFM_HCM_Q07 - 0105 B4 Era Town - MART
A25: =XLOOKUP(C25,H:H,G:G) -> BVB | B25: HCM 1 | C25: KFM_HCM_Q07 - 43 Bùi Văn Ba - MINI | G25: SSR | H25: KFM_HCM_NBE - SH14-15 Saigon South Residences - MINI | I25: HCM 4 | K25: HCM 20 | L25: GSM 20 | M25: Phạm Hữu Chương | O25: =ROW()-1 -> 24 | P25: 18/3/23 | Q25: KFM_HCM_TDU - 305 Nguyễn Duy Trinh - MART | R25: RIVER | S25: HCM 020-Phạm Hữu Chương | T25: =VLOOKUP(Q25,'Lịch kiểm kê 2025'!E:E,1,0) -> KFM_HCM_TDU - 305 Nguyễn Duy Trinh - MART
A26: =XLOOKUP(C26,H:H,G:G) -> TSO | B26: HCM 5 | C26: KFM_HCM_Q10 - BB17 Trường Sơn - MART | G26: VGP | H26: KFM_HCM_TDU - S06.06 Vinhomes Grand Park - MINI | I26: HCM 5 | O26: =ROW()-1 -> 25 | P26: 23/3/23 | Q26: KFM_HCM_TDU - 160A Nguyễn Thị Định - MINI | R26: RIVER | S26: HCM 019-Trần Thanh Hiền | T26: =VLOOKUP(Q26,'Lịch kiểm kê 2025'!E:E,1,0) -> KFM_HCM_TDU - 160A Nguyễn Thị Định - MINI
A27: =XLOOKUP(C27,H:H,G:G) -> Q7R | B27: HCM 1 | C27: KFM_HCM_Q07 - Lô CD L1-12 Q7 Riverside Đào Trí - MINI | G27: VH3 | H27: KFM_HCM_TDU - S1.05 Vinhomes Grand Park - MINI | I27: HCM 5 | O27: =ROW()-1 -> 26 | P27: 19/5/23 | Q27: KFM_HCM_GVA - 195 Thống Nhất - MART | R27: RIVER | S27: HCM 008-Huỳnh Ngọc Phương | T27: =VLOOKUP(Q27,'Lịch kiểm kê 2025'!E:E,1,0) -> KFM_HCM_GVA - 195 Thống Nhất - MART
A28: =XLOOKUP(C28,H:H,G:G) -> SFR | B28: HCM 2 | C28: KFM_HCM_TDU - D1-1.24 SAFIRA Khang Điền - MINI | G28: VH4 | H28: KFM_HCM_TDU - S07.02 Vinhomes Grand Park - MINI | I28: HCM 5 | O28: =ROW()-1 -> 27 | P28: 44932 | Q28: KFM_HCM_Q12 - 678 Nguyễn Văn Quá - MART | R28: RIVER | S28: HCM 009-Lâm Văn Tú | T28: =VLOOKUP(Q28,'Lịch kiểm kê 2025'!E:E,1,0) -> KFM_HCM_Q12 - 678 Nguyễn Văn Quá - MART
A29: =XLOOKUP(C29,H:H,G:G) -> QHG | B29: HCM 5 | C29: KFM_HCM_TDU - 59 Quốc Hương - MINI | G29: VH2 | H29: KFM_HCM_TDU - S10.02 Vinhomes Grand Park - MINI | I29: HCM 5 | O29: =ROW()-1 -> 28 | P29: 45114 | Q29: KFM_HCM_BCH - 511 Quốc Lộ 50 - MART | R29: RIVER | T29: =VLOOKUP(Q29,'Lịch kiểm kê 2025'!E:E,1,0) -> KFM_HCM_BCH - 511 Quốc lộ 50 - MART
A30: =XLOOKUP(C30,H:H,G:G) -> DXH | B30: HCM 2 | C30: KFM_HCM_TDU - 539 Đỗ Xuân Hợp - MINI | G30: VH5 | H30: KFM_HCM_TDU - S03.05 Vinhomes Grand Park - MINI | I30: HCM 5 | O30: =ROW()-1 -> 29 | P30: 15/7/23 | Q30: KFM_HCM_TDU - 539 Đỗ Xuân Hợp - MINI | R30: RIVER | S30: HCM 006-Nguyễn Đình Vũ | T30: =VLOOKUP(Q30,'Lịch kiểm kê 2025'!E:E,1,0) -> KFM_HCM_TDU - 539 Đỗ Xuân Hợp - MINI
